Workbook

Sheet 使い方
A1: 営業時間方針 FC企業ヒアリングシート
A2: 出典：焼肉事業部エリア編成（2026.07.01）／FC店舗一覧Excel E列（企業）。作成日 2026-10-06
A4: ヒアリング内容
A5: A：23時完全閉店 | B5: 23:00 にお客様退店・閉店を完了する運用
A6: B：最終入店から100分確保 | B6: 最終入店のお客様に100分間のお食事時間を確保し、その後閉店する運用（例：最終入店 21:20 → 閉店 23:00）
A8: シート構成
A9: 集計 | B9: ブロック・AM別の回答状況（自動集計。入力不要）
A10: 各ブロックシート | B10: AMごと・企業ごとに1行。黄色セルにヒアリング結果を入力
A11: 店舗別明細 | B11: FC全店舗の一覧。企業回答が自動反映。店舗ごとに例外がある場合のみ黄色セルに入力
A13: 入力ルール
A14: 黄色セル | B14: 入力欄（それ以外は数式・マスタなので編集不要）
A15: 回答 | B15: プルダウンから選択：A：23時完全閉店 / B：最終入店から100分確保 / 店舗により異なる / 検討中
A16: 店舗により異なる | B16: 企業回答で選んだ場合は「店舗別明細」で各店舗の回答を入力
A18: 入力例 | B18: 2026/10/15 | 代表取締役 山田様 | B：最終入店から100分確保 | 遅い時間帯の売上を維持したい | 21時台の人員確保 | 2026年12月〜
A20: 備考 | B20: 特急レーンブロック（小竹・フォン・板尾・梅木エリア）はFC店舗がないため対象外
A21: 備考 | B21: 同一企業を複数AMが担当しているケース（㈱本久：片寄・佐藤(恵)・松山／㈱桜家：岡村・谷本）は、AM間で回答をすり合わせてください

Sheet 集計
A1: ヒアリング進捗・回答集計
A2: 全セル自動計算（入力不要）
A4: ブロック | B4: AM | C4: 対象 企業数 | D4: 回答済 | E4: 未回答 | F4: 進捗率 | G4: A： 23時完全閉店 | H4: B： 最終入店から100分確保 | I4: 店舗により異なる | J4: 検討中 | K4: 対象 店舗数 | L4: 店舗方針A | M4: 店舗方針B
A5: 東日本 第一ブロック | B5: 星 雄二 | C5: =COUNTIF(東日本第一ブロック!$D$5:$D$11,B5) -> 2 | D5: =COUNTIFS(東日本第一ブロック!$D$5:$D$11,B5,東日本第一ブロック!$J$5:$J$11,"<>") -> 0 | E5: =C5-D5 -> 2 | F5: =IF(C5=0,0,D5/C5) -> 0 | G5: =COUNTIFS(東日本第一ブロック!$D$5:$D$11,$B5,東日本第一ブロック!$J$5:$J$11,"A：23時完全閉店") -> 0 | H5: =COUNTIFS(東日本第一ブロック!$D$5:$D$11,$B5,東日本第一ブロック!$J$5:$J$11,"B：最終入店から100分確保") -> 0 | I5: =COUNTIFS(東日本第一ブロック!$D$5:$D$11,$B5,東日本第一ブロック!$J$5:$J$11,"店舗により異なる") -> 0 | J5: =COUNTIFS(東日本第一ブロック!$D$5:$D$11,$B5,東日本第一ブロック!$J$5:$J$11,"検討中") -> 0 | K5: =COUNTIF(店舗別明細!$B$5:$B$134,B5) -> 5 | L5: =COUNTIFS(店舗別明細!$B$5:$B$134,B5,店舗別明細!$H$5:$H$134,"A：23時完全閉店") -> 0 | M5: =COUNTIFS(店舗別明細!$B$5:$B$134,B5,店舗別明細!$H$5:$H$134,"B：最終入店から100分確保") -> 0
A6: 東日本 第一ブロック | B6: 佐々木 潤 | C6: =COUNTIF(東日本第一ブロック!$D$5:$D$11,B6) -> 2 | D6: =COUNTIFS(東日本第一ブロック!$D$5:$D$11,B6,東日本第一ブロック!$J$5:$J$11,"<>") -> 0 | E6: =C6-D6 -> 2 | F6: =IF(C6=0,0,D6/C6) -> 0 | G6: =COUNTIFS(東日本第一ブロック!$D$5:$D$11,$B6,東日本第一ブロック!$J$5:$J$11,"A：23時完全閉店") -> 0 | H6: =COUNTIFS(東日本第一ブロック!$D$5:$D$11,$B6,東日本第一ブロック!$J$5:$J$11,"B：最終入店から100分確保") -> 0 | I6: =COUNTIFS(東日本第一ブロック!$D$5:$D$11,$B6,東日本第一ブロック!$J$5:$J$11,"店舗により異なる") -> 0 | J6: =COUNTIFS(東日本第一ブロック!$D$5:$D$11,$B6,東日本第一ブロック!$J$5:$J$11,"検討中") -> 0 | K6: =COUNTIF(店舗別明細!$B$5:$B$134,B6) -> 3 | L6: =COUNTIFS(店舗別明細!$B$5:$B$134,B6,店舗別明細!$H$5:$H$134,"A：23時完全閉店") -> 0 | M6: =COUNTIFS(店舗別明細!$B$5:$B$134,B6,店舗別明細!$H$5:$H$134,"B：最終入店から100分確保") -> 0
A7: 東日本 第一ブロック | B7: 平田 裕治 | C7: =COUNTIF(東日本第一ブロック!$D$5:$D$11,B7) -> 1 | D7: =COUNTIFS(東日本第一ブロック!$D$5:$D$11,B7,東日本第一ブロック!$J$5:$J$11,"<>") -> 0 | E7: =C7-D7 -> 1 | F7: =IF(C7=0,0,D7/C7) -> 0 | G7: =COUNTIFS(東日本第一ブロック!$D$5:$D$11,$B7,東日本第一ブロック!$J$5:$J$11,"A：23時完全閉店") -> 0 | H7: =COUNTIFS(東日本第一ブロック!$D$5:$D$11,$B7,東日本第一ブロック!$J$5:$J$11,"B：最終入店から100分確保") -> 0 | I7: =COUNTIFS(東日本第一ブロック!$D$5:$D$11,$B7,東日本第一ブロック!$J$5:$J$11,"店舗により異なる") -> 0 | J7: =COUNTIFS(東日本第一ブロック!$D$5:$D$11,$B7,東日本第一ブロック!$J$5:$J$11,"検討中") -> 0 | K7: =COUNTIF(店舗別明細!$B$5:$B$134,B7) -> 5 | L7: =COUNTIFS(店舗別明細!$B$5:$B$134,B7,店舗別明細!$H$5:$H$134,"A：23時完全閉店") -> 0 | M7: =COUNTIFS(店舗別明細!$B$5:$B$134,B7,店舗別明細!$H$5:$H$134,"B：最終入店から100分確保") -> 0
A8: 東日本 第一ブロック | B8: 西山 幸大 | C8: =COUNTIF(東日本第一ブロック!$D$5:$D$11,B8) -> 2 | D8: =COUNTIFS(東日本第一ブロック!$D$5:$D$11,B8,東日本第一ブロック!$J$5:$J$11,"<>") -> 0 | E8: =C8-D8 -> 2 | F8: =IF(C8=0,0,D8/C8) -> 0 | G8: =COUNTIFS(東日本第一ブロック!$D$5:$D$11,$B8,東日本第一ブロック!$J$5:$J$11,"A：23時完全閉店") -> 0 | H8: =COUNTIFS(東日本第一ブロック!$D$5:$D$11,$B8,東日本第一ブロック!$J$5:$J$11,"B：最終入店から100分確保") -> 0 | I8: =COUNTIFS(東日本第一ブロック!$D$5:$D$11,$B8,東日本第一ブロック!$J$5:$J$11,"店舗により異なる") -> 0 | J8: =COUNTIFS(東日本第一ブロック!$D$5:$D$11,$B8,東日本第一ブロック!$J$5:$J$11,"検討中") -> 0 | K8: =COUNTIF(店舗別明細!$B$5:$B$134,B8) -> 11 | L8: =COUNTIFS(店舗別明細!$B$5:$B$134,B8,店舗別明細!$H$5:$H$134,"A：23時完全閉店") -> 0 | M8: =COUNTIFS(店舗別明細!$B$5:$B$134,B8,店舗別明細!$H$5:$H$134,"B：最終入店から100分確保") -> 0
A9: 東日本 第一ブロック 計 | B9: BL：中村 卓登 | C9: =SUM(C5:C8) -> 7 | D9: =SUM(D5:D8) -> 0 | E9: =SUM(E5:E8) -> 7 | F9: =IF(C9=0,0,D9/C9) -> 0 | G9: =SUM(G5:G8) -> 0 | H9: =SUM(H5:H8) -> 0 | I9: =SUM(I5:I8) -> 0 | J9: =SUM(J5:J8) -> 0 | K9: =SUM(K5:K8) -> 24 | L9: =SUM(L5:L8) -> 0 | M9: =SUM(M5:M8) -> 0
A10: 東日本 第二ブロック | B10: 片寄 蒼 | C10: =COUNTIF(東日本第二ブロック!$D$5:$D$8,B10) -> 1 | D10: =COUNTIFS(東日本第二ブロック!$D$5:$D$8,B10,東日本第二ブロック!$J$5:$J$8,"<>") -> 0 | E10: =C10-D10 -> 1 | F10: =IF(C10=0,0,D10/C10) -> 0 | G10: =COUNTIFS(東日本第二ブロック!$D$5:$D$8,$B10,東日本第二ブロック!$J$5:$J$8,"A：23時完全閉店") -> 0 | H10: =COUNTIFS(東日本第二ブロック!$D$5:$D$8,$B10,東日本第二ブロック!$J$5:$J$8,"B：最終入店から100分確保") -> 0 | I10: =COUNTIFS(東日本第二ブロック!$D$5:$D$8,$B10,東日本第二ブロック!$J$5:$J$8,"店舗により異なる") -> 0 | J10: =COUNTIFS(東日本第二ブロック!$D$5:$D$8,$B10,東日本第二ブロック!$J$5:$J$8,"検討中") -> 0 | K10: =COUNTIF(店舗別明細!$B$5:$B$134,B10) -> 6 | L10: =COUNTIFS(店舗別明細!$B$5:$B$134,B10,店舗別明細!$H$5:$H$134,"A：23時完全閉店") -> 0 | M10: =COUNTIFS(店舗別明細!$B$5:$B$134,B10,店舗別明細!$H$5:$H$134,"B：最終入店から100分確保") -> 0
A11: 東日本 第二ブロック | B11: 永田 翔馬 | C11: =COUNTIF(東日本第二ブロック!$D$5:$D$8,B11) -> 1 | D11: =COUNTIFS(東日本第二ブロック!$D$5:$D$8,B11,東日本第二ブロック!$J$5:$J$8,"<>") -> 0 | E11: =C11-D11 -> 1 | F11: =IF(C11=0,0,D11/C11) -> 0 | G11: =COUNTIFS(東日本第二ブロック!$D$5:$D$8,$B11,東日本第二ブロック!$J$5:$J$8,"A：23時完全閉店") -> 0 | H11: =COUNTIFS(東日本第二ブロック!$D$5:$D$8,$B11,東日本第二ブロック!$J$5:$J$8,"B：最終入店から100分確保") -> 0 | I11: =COUNTIFS(東日本第二ブロック!$D$5:$D$8,$B11,東日本第二ブロック!$J$5:$J$8,"店舗により異なる") -> 0 | J11: =COUNTIFS(東日本第二ブロック!$D$5:$D$8,$B11,東日本第二ブロック!$J$5:$J$8,"検討中") -> 0 | K11: =COUNTIF(店舗別明細!$B$5:$B$134,B11) -> 3 | L11: =COUNTIFS(店舗別明細!$B$5:$B$134,B11,店舗別明細!$H$5:$H$134,"A：23時完全閉店") -> 0 | M11: =COUNTIFS(店舗別明細!$B$5:$B$134,B11,店舗別明細!$H$5:$H$134,"B：最終入店から100分確保") -> 0
A12: 東日本 第二ブロック | B12: 酒井 胤樹 | C12: =COUNTIF(東日本第二ブロック!$D$5:$D$8,B12) -> 1 | D12: =COUNTIFS(東日本第二ブロック!$D$5:$D$8,B12,東日本第二ブロック!$J$5:$J$8,"<>") -> 0 | E12: =C12-D12 -> 1 | F12: =IF(C12=0,0,D12/C12) -> 0 | G12: =COUNTIFS(東日本第二ブロック!$D$5:$D$8,$B12,東日本第二ブロック!$J$5:$J$8,"A：23時完全閉店") -> 0 | H12: =COUNTIFS(東日本第二ブロック!$D$5:$D$8,$B12,東日本第二ブロック!$J$5:$J$8,"B：最終入店から100分確保") -> 0 | I12: =COUNTIFS(東日本第二ブロック!$D$5:$D$8,$B12,東日本第二ブロック!$J$5:$J$8,"店舗により異なる") -> 0 | J12: =COUNTIFS(東日本第二ブロック!$D$5:$D$8,$B12,東日本第二ブロック!$J$5:$J$8,"検討中") -> 0 | K12: =COUNTIF(店舗別明細!$B$5:$B$134,B12) -> 7 | L12: =COUNTIFS(店舗別明細!$B$5:$B$134,B12,店舗別明細!$H$5:$H$134,"A：23時完全閉店") -> 0 | M12: =COUNTIFS(店舗別明細!$B$5:$B$134,B12,店舗別明細!$H$5:$H$134,"B：最終入店から100分確保") -> 0
A13: 東日本 第二ブロック | B13: 佐藤 恵介 | C13: =COUNTIF(東日本第二ブロック!$D$5:$D$8,B13) -> 1 | D13: =COUNTIFS(東日本第二ブロック!$D$5:$D$8,B13,東日本第二ブロック!$J$5:$J$8,"<>") -> 0 | E13: =C13-D13 -> 1 | F13: =IF(C13=0,0,D13/C13) -> 0 | G13: =COUNTIFS(東日本第二ブロック!$D$5:$D$8,$B13,東日本第二ブロック!$J$5:$J$8,"A：23時完全閉店") -> 0 | H13: =COUNTIFS(東日本第二ブロック!$D$5:$D$8,$B13,東日本第二ブロック!$J$5:$J$8,"B：最終入店から100分確保") -> 0 | I13: =COUNTIFS(東日本第二ブロック!$D$5:$D$8,$B13,東日本第二ブロック!$J$5:$J$8,"店舗により異なる") -> 0 | J13: =COUNTIFS(東日本第二ブロック!$D$5:$D$8,$B13,東日本第二ブロック!$J$5:$J$8,"検討中") -> 0 | K13: =COUNTIF(店舗別明細!$B$5:$B$134,B13) -> 2 | L13: =COUNTIFS(店舗別明細!$B$5:$B$134,B13,店舗別明細!$H$5:$H$134,"A：23時完全閉店") -> 0 | M13: =COUNTIFS(店舗別明細!$B$5:$B$134,B13,店舗別明細!$H$5:$H$134,"B：最終入店から100分確保") -> 0
A14: 東日本 第二ブロック 計 | B14: BL：渡辺 塁登 | C14: =SUM(C10:C13) -> 4 | D14: =SUM(D10:D13) -> 0 | E14: =SUM(E10:E13) -> 4 | F14: =IF(C14=0,0,D14/C14) -> 0 | G14: =SUM(G10:G13) -> 0 | H14: =SUM(H10:H13) -> 0 | I14: =SUM(I10:I13) -> 0 | J14: =SUM(J10:J13) -> 0 | K14: =SUM(K10:K13) -> 18 | L14: =SUM(L10:L13) -> 0 | M14: =SUM(M10:M13) -> 0
A15: 西日本 第一ブロック | B15: 松山 哲弘 | C15: =COUNTIF(西日本第一ブロック!$D$5:$D$12,B15) -> 2 | D15: =COUNTIFS(西日本第一ブロック!$D$5:$D$12,B15,西日本第一ブロック!$J$5:$J$12,"<>") -> 0 | E15: =C15-D15 -> 2 | F15: =IF(C15=0,0,D15/C15) -> 0 | G15: =COUNTIFS(西日本第一ブロック!$D$5:$D$12,$B15,西日本第一ブロック!$J$5:$J$12,"A：23時完全閉店") -> 0 | H15: =COUNTIFS(西日本第一ブロック!$D$5:$D$12,$B15,西日本第一ブロック!$J$5:$J$12,"B：最終入店から100分確保") -> 0 | I15: =COUNTIFS(西日本第一ブロック!$D$5:$D$12,$B15,西日本第一ブロック!$J$5:$J$12,"店舗により異なる") -> 0 | J15: =COUNTIFS(西日本第一ブロック!$D$5:$D$12,$B15,西日本第一ブロック!$J$5:$J$12,"検討中") -> 0 | K15: =COUNTIF(店舗別明細!$B$5:$B$134,B15) -> 3 | L15: =COUNTIFS(店舗別明細!$B$5:$B$134,B15,店舗別明細!$H$5:$H$134,"A：23時完全閉店") -> 0 | M15: =COUNTIFS(店舗別明細!$B$5:$B$134,B15,店舗別明細!$H$5:$H$134,"B：最終入店から100分確保") -> 0
A16: 西日本 第一ブロック | B16: 金 ヨンギョン | C16: =COUNTIF(西日本第一ブロック!$D$5:$D$12,B16) -> 2 | D16: =COUNTIFS(西日本第一ブロック!$D$5:$D$12,B16,西日本第一ブロック!$J$5:$J$12,"<>") -> 0 | E16: =C16-D16 -> 2 | F16: =IF(C16=0,0,D16/C16) -> 0 | G16: =COUNTIFS(西日本第一ブロック!$D$5:$D$12,$B16,西日本第一ブロック!$J$5:$J$12,"A：23時完全閉店") -> 0 | H16: =COUNTIFS(西日本第一ブロック!$D$5:$D$12,$B16,西日本第一ブロック!$J$5:$J$12,"B：最終入店から100分確保") -> 0 | I16: =COUNTIFS(西日本第一ブロック!$D$5:$D$12,$B16,西日本第一ブロック!$J$5:$J$12,"店舗により異なる") -> 0 | J16: =COUNTIFS(西日本第一ブロック!$D$5:$D$12,$B16,西日本第一ブロック!$J$5:$J$12,"検討中") -> 0 | K16: =COUNTIF(店舗別明細!$B$5:$B$134,B16) -> 3 | L16: =COUNTIFS(店舗別明細!$B$5:$B$134,B16,店舗別明細!$H$5:$H$134,"A：23時完全閉店") -> 0 | M16: =COUNTIFS(店舗別明細!$B$5:$B$134,B16,店舗別明細!$H$5:$H$134,"B：最終入店から100分確保") -> 0
A17: 西日本 第一ブロック | B17: 名越 康祐 | C17: =COUNTIF(西日本第一ブロック!$D$5:$D$12,B17) -> 3 | D17: =COUNTIFS(西日本第一ブロック!$D$5:$D$12,B17,西日本第一ブロック!$J$5:$J$12,"<>") -> 0 | E17: =C17-D17 -> 3 | F17: =IF(C17=0,0,D17/C17) -> 0 | G17: =COUNTIFS(西日本第一ブロック!$D$5:$D$12,$B17,西日本第一ブロック!$J$5:$J$12,"A：23時完全閉店") -> 0 | H17: =COUNTIFS(西日本第一ブロック!$D$5:$D$12,$B17,西日本第一ブロック!$J$5:$J$12,"B：最終入店から100分確保") -> 0 | I17: =COUNTIFS(西日本第一ブロック!$D$5:$D$12,$B17,西日本第一ブロック!$J$5:$J$12,"店舗により異なる") -> 0 | J17: =COUNTIFS(西日本第一ブロック!$D$5:$D$12,$B17,西日本第一ブロック!$J$5:$J$12,"検討中") -> 0 | K17: =COUNTIF(店舗別明細!$B$5:$B$134,B17) -> 18 | L17: =COUNTIFS(店舗別明細!$B$5:$B$134,B17,店舗別明細!$H$5:$H$134,"A：23時完全閉店") -> 0 | M17: =COUNTIFS(店舗別明細!$B$5:$B$134,B17,店舗別明細!$H$5:$H$134,"B：最終入店から100分確保") -> 0
A18: 西日本 第一ブロック | B18: 髙谷 祥平 | C18: =COUNTIF(西日本第一ブロック!$D$5:$D$12,B18) -> 1 | D18: =COUNTIFS(西日本第一ブロック!$D$5:$D$12,B18,西日本第一ブロック!$J$5:$J$12,"<>") -> 0 | E18: =C18-D18 -> 1 | F18: =IF(C18=0,0,D18/C18) -> 0 | G18: =COUNTIFS(西日本第一ブロック!$D$5:$D$12,$B18,西日本第一ブロック!$J$5:$J$12,"A：23時完全閉店") -> 0 | H18: =COUNTIFS(西日本第一ブロック!$D$5:$D$12,$B18,西日本第一ブロック!$J$5:$J$12,"B：最終入店から100分確保") -> 0 | I18: =COUNTIFS(西日本第一ブロック!$D$5:$D$12,$B18,西日本第一ブロック!$J$5:$J$12,"店舗により異なる") -> 0 | J18: =COUNTIFS(西日本第一ブロック!$D$5:$D$12,$B18,西日本第一ブロック!$J$5:$J$12,"検討中") -> 0 | K18: =COUNTIF(店舗別明細!$B$5:$B$134,B18) -> 5 | L18: =COUNTIFS(店舗別明細!$B$5:$B$134,B18,店舗別明細!$H$5:$H$134,"A：23時完全閉店") -> 0 | M18: =COUNTIFS(店舗別明細!$B$5:$B$134,B18,店舗別明細!$H$5:$H$134,"B：最終入店から100分確保") -> 0
A19: 西日本 第一ブロック 計 | B19: BL：早川 元気 | C19: =SUM(C15:C18) -> 8 | D19: =SUM(D15:D18) -> 0 | E19: =SUM(E15:E18) -> 8 | F19: =IF(C19=0,0,D19/C19) -> 0 | G19: =SUM(G15:G18) -> 0 | H19: =SUM(H15:H18) -> 0 | I19: =SUM(I15:I18) -> 0 | J19: =SUM(J15:J18) -> 0 | K19: =SUM(K15:K18) -> 29 | L19: =SUM(L15:L18) -> 0 | M19: =SUM(M15:M18) -> 0
A20: 西日本 第二ブロック | B20: 上野 正裕 | C20: =COUNTIF(西日本第二ブロック!$D$5:$D$13,B20) -> 1 | D20: =COUNTIFS(西日本第二ブロック!$D$5:$D$13,B20,西日本第二ブロック!$J$5:$J$13,"<>") -> 0 | E20: =C20-D20 -> 1 | F20: =IF(C20=0,0,D20/C20) -> 0 | G20: =COUNTIFS(西日本第二ブロック!$D$5:$D$13,$B20,西日本第二ブロック!$J$5:$J$13,"A：23時完全閉店") -> 0 | H20: =COUNTIFS(西日本第二ブロック!$D$5:$D$13,$B20,西日本第二ブロック!$J$5:$J$13,"B：最終入店から100分確保") -> 0 | I20: =COUNTIFS(西日本第二ブロック!$D$5:$D$13,$B20,西日本第二ブロック!$J$5:$J$13,"店舗により異なる") -> 0 | J20: =COUNTIFS(西日本第二ブロック!$D$5:$D$13,$B20,西日本第二ブロック!$J$5:$J$13,"検討中") -> 0 | K20: =COUNTIF(店舗別明細!$B$5:$B$134,B20) -> 3 | L20: =COUNTIFS(店舗別明細!$B$5:$B$134,B20,店舗別明細!$H$5:$H$134,"A：23時完全閉店") -> 0 | M20: =COUNTIFS(店舗別明細!$B$5:$B$134,B20,店舗別明細!$H$5:$H$134,"B：最終入店から100分確保") -> 0
A21: 西日本 第二ブロック | B21: 武田 聖志 | C21: =COUNTIF(西日本第二ブロック!$D$5:$D$13,B21) -> 2 | D21: =COUNTIFS(西日本第二ブロック!$D$5:$D$13,B21,西日本第二ブロック!$J$5:$J$13,"<>") -> 0 | E21: =C21-D21 -> 2 | F21: =IF(C21=0,0,D21/C21) -> 0 | G21: =COUNTIFS(西日本第二ブロック!$D$5:$D$13,$B21,西日本第二ブロック!$J$5:$J$13,"A：23時完全閉店") -> 0 | H21: =COUNTIFS(西日本第二ブロック!$D$5:$D$13,$B21,西日本第二ブロック!$J$5:$J$13,"B：最終入店から100分確保") -> 0 | I21: =COUNTIFS(西日本第二ブロック!$D$5:$D$13,$B21,西日本第二ブロック!$J$5:$J$13,"店舗により異なる") -> 0 | J21: =COUNTIFS(西日本第二ブロック!$D$5:$D$13,$B21,西日本第二ブロック!$J$5:$J$13,"検討中") -> 0 | K21: =COUNTIF(店舗別明細!$B$5:$B$134,B21) -> 4 | L21: =COUNTIFS(店舗別明細!$B$5:$B$134,B21,店舗別明細!$H$5:$H$134,"A：23時完全閉店") -> 0 | M21: =COUNTIFS(店舗別明細!$B$5:$B$134,B21,店舗別明細!$H$5:$H$134,"B：最終入店から100分確保") -> 0
A22: 西日本 第二ブロック | B22: 古川 智彦 | C22: =COUNTIF(西日本第二ブロック!$D$5:$D$13,B22) -> 2 | D22: =COUNTIFS(西日本第二ブロック!$D$5:$D$13,B22,西日本第二ブロック!$J$5:$J$13,"<>") -> 0 | E22: =C22-D22 -> 2 | F22: =IF(C22=0,0,D22/C22) -> 0 | G22: =COUNTIFS(西日本第二ブロック!$D$5:$D$13,$B22,西日本第二ブロック!$J$5:$J$13,"A：23時完全閉店") -> 0 | H22: =COUNTIFS(西日本第二ブロック!$D$5:$D$13,$B22,西日本第二ブロック!$J$5:$J$13,"B：最終入店から100分確保") -> 0 | I22: =COUNTIFS(西日本第二ブロック!$D$5:$D$13,$B22,西日本第二ブロック!$J$5:$J$13,"店舗により異なる") -> 0 | J22: =COUNTIFS(西日本第二ブロック!$D$5:$D$13,$B22,西日本第二ブロック!$J$5:$J$13,"検討中") -> 0 | K22: =COUNTIF(店舗別明細!$B$5:$B$134,B22) -> 4 | L22: =COUNTIFS(店舗別明細!$B$5:$B$134,B22,店舗別明細!$H$5:$H$134,"A：23時完全閉店") -> 0 | M22: =COUNTIFS(店舗別明細!$B$5:$B$134,B22,店舗別明細!$H$5:$H$134,"B：最終入店から100分確保") -> 0
A23: 西日本 第二ブロック | B23: 岡村 愛理 | C23: =COUNTIF(西日本第二ブロック!$D$5:$D$13,B23) -> 1 | D23: =COUNTIFS(西日本第二ブロック!$D$5:$D$13,B23,西日本第二ブロック!$J$5:$J$13,"<>") -> 0 | E23: =C23-D23 -> 1 | F23: =IF(C23=0,0,D23/C23) -> 0 | G23: =COUNTIFS(西日本第二ブロック!$D$5:$D$13,$B23,西日本第二ブロック!$J$5:$J$13,"A：23時完全閉店") -> 0 | H23: =COUNTIFS(西日本第二ブロック!$D$5:$D$13,$B23,西日本第二ブロック!$J$5:$J$13,"B：最終入店から100分確保") -> 0 | I23: =COUNTIFS(西日本第二ブロック!$D$5:$D$13,$B23,西日本第二ブロック!$J$5:$J$13,"店舗により異なる") -> 0 | J23: =COUNTIFS(西日本第二ブロック!$D$5:$D$13,$B23,西日本第二ブロック!$J$5:$J$13,"検討中") -> 0 | K23: =COUNTIF(店舗別明細!$B$5:$B$134,B23) -> 2 | L23: =COUNTIFS(店舗別明細!$B$5:$B$134,B23,店舗別明細!$H$5:$H$134,"A：23時完全閉店") -> 0 | M23: =COUNTIFS(店舗別明細!$B$5:$B$134,B23,店舗別明細!$H$5:$H$134,"B：最終入店から100分確保") -> 0
A24: 西日本 第二ブロック | B24: 谷本 浩之 | C24: =COUNTIF(西日本第二ブロック!$D$5:$D$13,B24) -> 2 | D24: =COUNTIFS(西日本第二ブロック!$D$5:$D$13,B24,西日本第二ブロック!$J$5:$J$13,"<>") -> 0 | E24: =C24-D24 -> 2 | F24: =IF(C24=0,0,D24/C24) -> 0 | G24: =COUNTIFS(西日本第二ブロック!$D$5:$D$13,$B24,西日本第二ブロック!$J$5:$J$13,"A：23時完全閉店") -> 0 | H24: =COUNTIFS(西日本第二ブロック!$D$5:$D$13,$B24,西日本第二ブロック!$J$5:$J$13,"B：最終入店から100分確保") -> 0 | I24: =COUNTIFS(西日本第二ブロック!$D$5:$D$13,$B24,西日本第二ブロック!$J$5:$J$13,"店舗により異なる") -> 0 | J24: =COUNTIFS(西日本第二ブロック!$D$5:$D$13,$B24,西日本第二ブロック!$J$5:$J$13,"検討中") -> 0 | K24: =COUNTIF(店舗別明細!$B$5:$B$134,B24) -> 3 | L24: =COUNTIFS(店舗別明細!$B$5:$B$134,B24,店舗別明細!$H$5:$H$134,"A：23時完全閉店") -> 0 | M24: =COUNTIFS(店舗別明細!$B$5:$B$134,B24,店舗別明細!$H$5:$H$134,"B：最終入店から100分確保") -> 0
A25: 西日本 第二ブロック | B25: 陳 学 | C25: =COUNTIF(西日本第二ブロック!$D$5:$D$13,B25) -> 1 | D25: =COUNTIFS(西日本第二ブロック!$D$5:$D$13,B25,西日本第二ブロック!$J$5:$J$13,"<>") -> 0 | E25: =C25-D25 -> 1 | F25: =IF(C25=0,0,D25/C25) -> 0 | G25: =COUNTIFS(西日本第二ブロック!$D$5:$D$13,$B25,西日本第二ブロック!$J$5:$J$13,"A：23時完全閉店") -> 0 | H25: =COUNTIFS(西日本第二ブロック!$D$5:$D$13,$B25,西日本第二ブロック!$J$5:$J$13,"B：最終入店から100分確保") -> 0 | I25: =COUNTIFS(西日本第二ブロック!$D$5:$D$13,$B25,西日本第二ブロック!$J$5:$J$13,"店舗により異なる") -> 0 | J25: =COUNTIFS(西日本第二ブロック!$D$5:$D$13,$B25,西日本第二ブロック!$J$5:$J$13,"検討中") -> 0 | K25: =COUNTIF(店舗別明細!$B$5:$B$134,B25) -> 43 | L25: =COUNTIFS(店舗別明細!$B$5:$B$134,B25,店舗別明細!$H$5:$H$134,"A：23時完全閉店") -> 0 | M25: =COUNTIFS(店舗別明細!$B$5:$B$134,B25,店舗別明細!$H$5:$H$134,"B：最終入店から100分確保") -> 0
A26: 西日本 第二ブロック 計 | B26: BL：吉田 千秋 | C26: =SUM(C20:C25) -> 9 | D26: =SUM(D20:D25) -> 0 | E26: =SUM(E20:E25) -> 9 | F26: =IF(C26=0,0,D26/C26) -> 0 | G26: =SUM(G20:G25) -> 0 | H26: =SUM(H20:H25) -> 0 | I26: =SUM(I20:I25) -> 0 | J26: =SUM(J20:J25) -> 0 | K26: =SUM(K20:K25) -> 59 | L26: =SUM(L20:L25) -> 0 | M26: =SUM(M20:M25) -> 0
A27: 総計 | C27: =C9+C14+C19+C26 -> 28 | D27: =D9+D14+D19+D26 -> 0 | E27: =E9+E14+E19+E26 -> 28 | F27: =IF(C27=0,0,D27/C27) -> 0 | G27: =G9+G14+G19+G26 -> 0 | H27: =H9+H14+H19+H26 -> 0 | I27: =I9+I14+I19+I26 -> 0 | J27: =J9+J14+J19+J26 -> 0 | K27: =K9+K14+K19+K26 -> 130 | L27: =L9+L14+L19+L26 -> 0 | M27: =M9+M14+M19+M26 -> 0
A29: ※店舗方針A/Bは「店舗別明細」の最終方針（企業回答＋店舗個別回答）で集計

Sheet 東日本第一ブロック
A1: 東日本 第一ブロック ブロック長：中村 卓登
A2: 黄色セルにヒアリング結果を入力してください。回答はプルダウンから選択。
A4: No | B4: ブロック | C4: ブロック長 | D4: AM | E4: 企業名 | F4: 対象 店舗数 | G4: 対象店舗 | H4: ヒアリング 実施日 | I4: ご回答者 （役職・氏名） | J4: 回答 | K4: 選択理由 | L4: 懸念点・ 本部への要望 | M4: 実施 希望時期 | N4: 備考 | O4: key
A5: 1 | B5: 東日本 第一ブロック | C5: 中村 卓登 | D5: 星 雄二 | E5: ㈱グローバル・ノースジャパン | F5: =COUNTIFS(店舗別明細!$B$5:$B$134,D5,店舗別明細!$C$5:$C$134,E5) -> 4 | G5: 函館桔梗、秋田広面、青森観光通り、弘前 | O5: =D5&"|"&E5 -> 星 雄二|㈱グローバル・ノースジャパン
A6: 2 | B6: 東日本 第一ブロック | C6: 中村 卓登 | D6: 星 雄二 | E6: ㈱北星 | F6: =COUNTIFS(店舗別明細!$B$5:$B$134,D6,店舗別明細!$C$5:$C$134,E6) -> 1 | G6: 千歳 | O6: =D6&"|"&E6 -> 星 雄二|㈱北星
A7: 3 | B7: 東日本 第一ブロック | C7: 中村 卓登 | D7: 佐々木 潤 | E7: ㈱MAGNETIC | F7: =COUNTIFS(店舗別明細!$B$5:$B$134,D7,店舗別明細!$C$5:$C$134,E7) -> 1 | G7: 仙台八乙女 | O7: =D7&"|"&E7 -> 佐々木 潤|㈱MAGNETIC
A8: 4 | B8: 東日本 第一ブロック | C8: 中村 卓登 | D8: 佐々木 潤 | E8: ㈱テイザンフーズ | F8: =COUNTIFS(店舗別明細!$B$5:$B$134,D8,店舗別明細!$C$5:$C$134,E8) -> 2 | G8: 仙台西多賀、古川 | O8: =D8&"|"&E8 -> 佐々木 潤|㈱テイザンフーズ
A9: 5 | B9: 東日本 第一ブロック | C9: 中村 卓登 | D9: 平田 裕治 | E9: ㈱ホコタ | F9: =COUNTIFS(店舗別明細!$B$5:$B$134,D9,店舗別明細!$C$5:$C$134,E9) -> 5 | G9: 守谷、水戸姫子、水戸南インター、那珂、日立金沢 | O9: =D9&"|"&E9 -> 平田 裕治|㈱ホコタ
A10: 6 | B10: 東日本 第一ブロック | C10: 中村 卓登 | D10: 西山 幸大 | E10: ㈱サンフジフーズ | F10: =COUNTIFS(店舗別明細!$B$5:$B$134,D10,店舗別明細!$C$5:$C$134,E10) -> 6 | G10: 上尾、伊勢原、所沢、二ツ家、月見町、相模原駅前 | O10: =D10&"|"&E10 -> 西山 幸大|㈱サンフジフーズ
A11: 7 | B11: 東日本 第一ブロック | C11: 中村 卓登 | D11: 西山 幸大 | E11: ㈱しおさいフーズ | F11: =COUNTIFS(店舗別明細!$B$5:$B$134,D11,店舗別明細!$C$5:$C$134,E11) -> 5 | G11: 新潟駅南、新津、新潟河渡、新潟小新、長岡 | O11: =D11&"|"&E11 -> 西山 幸大|㈱しおさいフーズ

Sheet 東日本第二ブロック
A1: 東日本 第二ブロック ブロック長：渡辺 塁登
A2: 黄色セルにヒアリング結果を入力してください。回答はプルダウンから選択。
A4: No | B4: ブロック | C4: ブロック長 | D4: AM | E4: 企業名 | F4: 対象 店舗数 | G4: 対象店舗 | H4: ヒアリング 実施日 | I4: ご回答者 （役職・氏名） | J4: 回答 | K4: 選択理由 | L4: 懸念点・ 本部への要望 | M4: 実施 希望時期 | N4: 備考 | O4: key
A5: 1 | B5: 東日本 第二ブロック | C5: 渡辺 塁登 | D5: 片寄 蒼 | E5: ㈱本久 | F5: =COUNTIFS(店舗別明細!$B$5:$B$134,D5,店舗別明細!$C$5:$C$134,E5) -> 6 | G5: 三郷、太田、春日部、伊勢崎、久喜、羽生 | O5: =D5&"|"&E5 -> 片寄 蒼|㈱本久
A6: 2 | B6: 東日本 第二ブロック | C6: 渡辺 塁登 | D6: 永田 翔馬 | E6: 株式会社フードフォワード | F6: =COUNTIFS(店舗別明細!$B$5:$B$134,D6,店舗別明細!$C$5:$C$134,E6) -> 3 | G6: つくば、八千代、我孫子 | O6: =D6&"|"&E6 -> 永田 翔馬|株式会社フードフォワード
A7: 3 | B7: 東日本 第二ブロック | C7: 渡辺 塁登 | D7: 酒井 胤樹 | E7: ノヴィルフォーワード㈱ | F7: =COUNTIFS(店舗別明細!$B$5:$B$134,D7,店舗別明細!$C$5:$C$134,E7) -> 7 | G7: おゆみ野、鹿嶋、市原五井、佐倉寺崎、富里、成田、東金 | O7: =D7&"|"&E7 -> 酒井 胤樹|ノヴィルフォーワード㈱
A8: 4 | B8: 東日本 第二ブロック | C8: 渡辺 塁登 | D8: 佐藤 恵介 | E8: ㈱本久 | F8: =COUNTIFS(店舗別明細!$B$5:$B$134,D8,店舗別明細!$C$5:$C$134,E8) -> 2 | G8: 新座ひばりが丘、練馬石神井台 | O8: =D8&"|"&E8 -> 佐藤 恵介|㈱本久

Sheet 西日本第一ブロック
A1: 西日本 第一ブロック ブロック長：早川 元気
A2: 黄色セルにヒアリング結果を入力してください。回答はプルダウンから選択。
A4: No | B4: ブロック | C4: ブロック長 | D4: AM | E4: 企業名 | F4: 対象 店舗数 | G4: 対象店舗 | H4: ヒアリング 実施日 | I4: ご回答者 （役職・氏名） | J4: 回答 | K4: 選択理由 | L4: 懸念点・ 本部への要望 | M4: 実施 希望時期 | N4: 備考 | O4: key
A5: 1 | B5: 西日本 第一ブロック | C5: 早川 元気 | D5: 松山 哲弘 | E5: ㈱本久 | F5: =COUNTIFS(店舗別明細!$B$5:$B$134,D5,店舗別明細!$C$5:$C$134,E5) -> 2 | G5: 佐久平、上田 | O5: =D5&"|"&E5 -> 松山 哲弘|㈱本久
A6: 2 | B6: 西日本 第一ブロック | C6: 早川 元気 | D6: 松山 哲弘 | E6: 中信興業㈱ | F6: =COUNTIFS(店舗別明細!$B$5:$B$134,D6,店舗別明細!$C$5:$C$134,E6) -> 1 | G6: 松本あがた | O6: =D6&"|"&E6 -> 松山 哲弘|中信興業㈱
A7: 3 | B7: 西日本 第一ブロック | C7: 早川 元気 | D7: 金 ヨンギョン | E7: 日映㈱ | F7: =COUNTIFS(店舗別明細!$B$5:$B$134,D7,店舗別明細!$C$5:$C$134,E7) -> 2 | G7: 小黒、静岡流通通り | O7: =D7&"|"&E7 -> 金 ヨンギョン|日映㈱
A8: 4 | B8: 西日本 第一ブロック | C8: 早川 元気 | D8: 金 ヨンギョン | E8: ㈱呉竹荘 | F8: =COUNTIFS(店舗別明細!$B$5:$B$134,D8,店舗別明細!$C$5:$C$134,E8) -> 1 | G8: 志都呂 | O8: =D8&"|"&E8 -> 金 ヨンギョン|㈱呉竹荘
A9: 5 | B9: 西日本 第一ブロック | C9: 早川 元気 | D9: 名越 康祐 | E9: 豊田産業㈱ | F9: =COUNTIFS(店舗別明細!$B$5:$B$134,D9,店舗別明細!$C$5:$C$134,E9) -> 7 | G9: 梅坪、豊田浄水、三河安城、三好、西尾、元町、日進竹の山 | O9: =D9&"|"&E9 -> 名越 康祐|豊田産業㈱
A10: 6 | B10: 西日本 第一ブロック | C10: 早川 元気 | D10: 名越 康祐 | E10: ㈱食物語 | F10: =COUNTIFS(店舗別明細!$B$5:$B$134,D10,店舗別明細!$C$5:$C$134,E10) -> 10 | G10: 都城、霧島、宮崎新別府、宮崎恒久、延岡、大牟田、伊敷、帯山、薩摩川内、宮崎大工 | O10: =D10&"|"&E10 -> 名越 康祐|㈱食物語
A11: 7 | B11: 西日本 第一ブロック | C11: 早川 元気 | D11: 名越 康祐 | E11: ㈱名鉄ミライート | F11: =COUNTIFS(店舗別明細!$B$5:$B$134,D11,店舗別明細!$C$5:$C$134,E11) -> 1 | G11: 東海名和 | O11: =D11&"|"&E11 -> 名越 康祐|㈱名鉄ミライート
A12: 8 | B12: 西日本 第一ブロック | C12: 早川 元気 | D12: 髙谷 祥平 | E12: ㈱デイリーカフェ＆フーズ | F12: =COUNTIFS(店舗別明細!$B$5:$B$134,D12,店舗別明細!$C$5:$C$134,E12) -> 5 | G12: 鴨田、春日井大留、羽根、犬山、江南 | O12: =D12&"|"&E12 -> 髙谷 祥平|㈱デイリーカフェ＆フーズ

Sheet 西日本第二ブロック
A1: 西日本 第二ブロック ブロック長：吉田 千秋
A2: 黄色セルにヒアリング結果を入力してください。回答はプルダウンから選択。
A4: No | B4: ブロック | C4: ブロック長 | D4: AM | E4: 企業名 | F4: 対象 店舗数 | G4: 対象店舗 | H4: ヒアリング 実施日 | I4: ご回答者 （役職・氏名） | J4: 回答 | K4: 選択理由 | L4: 懸念点・ 本部への要望 | M4: 実施 希望時期 | N4: 備考 | O4: key
A5: 1 | B5: 西日本 第二ブロック | C5: 吉田 千秋 | D5: 上野 正裕 | E5: ㈱平和ダイニング | F5: =COUNTIFS(店舗別明細!$B$5:$B$134,D5,店舗別明細!$C$5:$C$134,E5) -> 3 | G5: 泉佐野、和泉中央、岸和田 | O5: =D5&"|"&E5 -> 上野 正裕|㈱平和ダイニング
A6: 2 | B6: 西日本 第二ブロック | C6: 吉田 千秋 | D6: 武田 聖志 | E6: ㈱コロンブス | F6: =COUNTIFS(店舗別明細!$B$5:$B$134,D6,店舗別明細!$C$5:$C$134,E6) -> 3 | G6: 岩出、国体道路、和歌山北 | O6: =D6&"|"&E6 -> 武田 聖志|㈱コロンブス
A7: 3 | B7: 西日本 第二ブロック | C7: 吉田 千秋 | D7: 武田 聖志 | E7: ㈱ヨロチョー | F7: =COUNTIFS(店舗別明細!$B$5:$B$134,D7,店舗別明細!$C$5:$C$134,E7) -> 1 | G7: 米子 | O7: =D7&"|"&E7 -> 武田 聖志|㈱ヨロチョー
A8: 4 | B8: 西日本 第二ブロック | C8: 吉田 千秋 | D8: 古川 智彦 | E8: ㈱エスフーズ | F8: =COUNTIFS(店舗別明細!$B$5:$B$134,D8,店舗別明細!$C$5:$C$134,E8) -> 1 | G8: 三原 | O8: =D8&"|"&E8 -> 古川 智彦|㈱エスフーズ
A9: 5 | B9: 西日本 第二ブロック | C9: 吉田 千秋 | D9: 古川 智彦 | E9: ノヴィルフロンティア㈱ | F9: =COUNTIFS(店舗別明細!$B$5:$B$134,D9,店舗別明細!$C$5:$C$134,E9) -> 3 | G9: イオンタウン宇多津、丸亀、新居浜 | O9: =D9&"|"&E9 -> 古川 智彦|ノヴィルフロンティア㈱
A10: 6 | B10: 西日本 第二ブロック | C10: 吉田 千秋 | D10: 岡村 愛理 | E10: ㈱桜家 | F10: =COUNTIFS(店舗別明細!$B$5:$B$134,D10,店舗別明細!$C$5:$C$134,E10) -> 2 | G10: 若松大鳥居、八女インター | O10: =D10&"|"&E10 -> 岡村 愛理|㈱桜家
A11: 7 | B11: 西日本 第二ブロック | C11: 吉田 千秋 | D11: 谷本 浩之 | E11: ㈲林田飼料 | F11: =COUNTIFS(店舗別明細!$B$5:$B$134,D11,店舗別明細!$C$5:$C$134,E11) -> 1 | G11: 時津 | O11: =D11&"|"&E11 -> 谷本 浩之|㈲林田飼料
A12: 8 | B12: 西日本 第二ブロック | C12: 吉田 千秋 | D12: 谷本 浩之 | E12: ㈱桜家 | F12: =COUNTIFS(店舗別明細!$B$5:$B$134,D12,店舗別明細!$C$5:$C$134,E12) -> 2 | G12: 大分光吉、小倉津田 | O12: =D12&"|"&E12 -> 谷本 浩之|㈱桜家
A13: 9 | B13: 西日本 第二ブロック | C13: 吉田 千秋 | D13: 陳 学 | E13: ㈱ｇlob | F13: =COUNTIFS(店舗別明細!$B$5:$B$134,D13,店舗別明細!$C$5:$C$134,E13) -> 43 | G13: 福岡千早、福岡原、盛岡盛南、福井大和田、熊本はません、広島緑井、松山衣山、徳島応神、那覇新都心、鹿児島宇宿、八戸城下、一日橋、北谷、吉田、蒲郡、砺波、小松、甲府昭和、鹿屋バイパス、上越セントラルスクエア、広島井口、松本村井、笠懸、旭川永山、福山王子、那覇久茂地、広島宇品、徳島沖浜、沖縄美里、名護、別府、東苗穂、三島、福山御幸、高知インター、半田、札幌新琴似、苫小牧、西条、帯広、焼津、北見、掛川 | O13: =D13&"|"&E13 -> 陳 学|㈱ｇlob

Sheet 店舗別明細
A1: FC店舗別明細
A2: 企業回答は各ブロックシートから自動反映。店舗ごとに企業回答と異なる場合のみ「店舗個別回答」を入力。
A4: ブロック | B4: AM | C4: 企業名 | D4: 店舗 コード | E4: 店舗名 | F4: 企業回答 （自動） | G4: 店舗個別回答 （例外時のみ） | H4: 最終方針 | I4: 現状の 営業終了時刻 | J4: 想定 最終入店時刻 | K4: B選択時の 閉店時刻（自動） | L4: 備考
A5: 東日本 第一ブロック | B5: 星 雄二 | C5: ㈱グローバル・ノースジャパン | D5: 2156 | E5: 函館桔梗 | F5: =IFERROR(IF(INDEX(東日本第一ブロック!$J$5:$J$11,MATCH(B5&"|"&C5,東日本第一ブロック!$O$5:$O$11,0))="","未回答",INDEX(東日本第一ブロック!$J$5:$J$11,MATCH(B5&"|"&C5,東日本第一ブロック!$O$5:$O$11,0))),"未回答") -> 未回答 | H5: =IF(G5<>"",G5,F5) -> 未回答 | K5: =IF(OR(J5="",LEFT(H5,1)<>"B"),"",MOD(J5+TIME(1,40,0),1))
A6: 東日本 第一ブロック | B6: 星 雄二 | C6: ㈱グローバル・ノースジャパン | D6: 2183 | E6: 秋田広面 | F6: =IFERROR(IF(INDEX(東日本第一ブロック!$J$5:$J$11,MATCH(B6&"|"&C6,東日本第一ブロック!$O$5:$O$11,0))="","未回答",INDEX(東日本第一ブロック!$J$5:$J$11,MATCH(B6&"|"&C6,東日本第一ブロック!$O$5:$O$11,0))),"未回答") -> 未回答 | H6: =IF(G6<>"",G6,F6) -> 未回答 | K6: =IF(OR(J6="",LEFT(H6,1)<>"B"),"",MOD(J6+TIME(1,40,0),1))
A7: 東日本 第一ブロック | B7: 星 雄二 | C7: ㈱グローバル・ノースジャパン | D7: 2253 | E7: 青森観光通り | F7: =IFERROR(IF(INDEX(東日本第一ブロック!$J$5:$J$11,MATCH(B7&"|"&C7,東日本第一ブロック!$O$5:$O$11,0))="","未回答",INDEX(東日本第一ブロック!$J$5:$J$11,MATCH(B7&"|"&C7,東日本第一ブロック!$O$5:$O$11,0))),"未回答") -> 未回答 | H7: =IF(G7<>"",G7,F7) -> 未回答 | K7: =IF(OR(J7="",LEFT(H7,1)<>"B"),"",MOD(J7+TIME(1,40,0),1))
A8: 東日本 第一ブロック | B8: 星 雄二 | C8: ㈱グローバル・ノースジャパン | D8: 2388 | E8: 弘前 | F8: =IFERROR(IF(INDEX(東日本第一ブロック!$J$5:$J$11,MATCH(B8&"|"&C8,東日本第一ブロック!$O$5:$O$11,0))="","未回答",INDEX(東日本第一ブロック!$J$5:$J$11,MATCH(B8&"|"&C8,東日本第一ブロック!$O$5:$O$11,0))),"未回答") -> 未回答 | H8: =IF(G8<>"",G8,F8) -> 未回答 | K8: =IF(OR(J8="",LEFT(H8,1)<>"B"),"",MOD(J8+TIME(1,40,0),1))
A9: 東日本 第一ブロック | B9: 星 雄二 | C9: ㈱北星 | D9: 2364 | E9: 千歳 | F9: =IFERROR(IF(INDEX(東日本第一ブロック!$J$5:$J$11,MATCH(B9&"|"&C9,東日本第一ブロック!$O$5:$O$11,0))="","未回答",INDEX(東日本第一ブロック!$J$5:$J$11,MATCH(B9&"|"&C9,東日本第一ブロック!$O$5:$O$11,0))),"未回答") -> 未回答 | H9: =IF(G9<>"",G9,F9) -> 未回答 | K9: =IF(OR(J9="",LEFT(H9,1)<>"B"),"",MOD(J9+TIME(1,40,0),1))
A10: 東日本 第一ブロック | B10: 佐々木 潤 | C10: ㈱MAGNETIC | D10: 2073 | E10: 仙台八乙女 | F10: =IFERROR(IF(INDEX(東日本第一ブロック!$J$5:$J$11,MATCH(B10&"|"&C10,東日本第一ブロック!$O$5:$O$11,0))="","未回答",INDEX(東日本第一ブロック!$J$5:$J$11,MATCH(B10&"|"&C10,東日本第一ブロック!$O$5:$O$11,0))),"未回答") -> 未回答 | H10: =IF(G10<>"",G10,F10) -> 未回答 | K10: =IF(OR(J10="",LEFT(H10,1)<>"B"),"",MOD(J10+TIME(1,40,0),1))
A11: 東日本 第一ブロック | B11: 佐々木 潤 | C11: ㈱テイザンフーズ | D11: 2196 | E11: 仙台西多賀 | F11: =IFERROR(IF(INDEX(東日本第一ブロック!$J$5:$J$11,MATCH(B11&"|"&C11,東日本第一ブロック!$O$5:$O$11,0))="","未回答",INDEX(東日本第一ブロック!$J$5:$J$11,MATCH(B11&"|"&C11,東日本第一ブロック!$O$5:$O$11,0))),"未回答") -> 未回答 | H11: =IF(G11<>"",G11,F11) -> 未回答 | K11: =IF(OR(J11="",LEFT(H11,1)<>"B"),"",MOD(J11+TIME(1,40,0),1))
A12: 東日本 第一ブロック | B12: 佐々木 潤 | C12: ㈱テイザンフーズ | D12: 2390 | E12: 古川 | F12: =IFERROR(IF(INDEX(東日本第一ブロック!$J$5:$J$11,MATCH(B12&"|"&C12,東日本第一ブロック!$O$5:$O$11,0))="","未回答",INDEX(東日本第一ブロック!$J$5:$J$11,MATCH(B12&"|"&C12,東日本第一ブロック!$O$5:$O$11,0))),"未回答") -> 未回答 | H12: =IF(G12<>"",G12,F12) -> 未回答 | K12: =IF(OR(J12="",LEFT(H12,1)<>"B"),"",MOD(J12+TIME(1,40,0),1))
A13: 東日本 第一ブロック | B13: 平田 裕治 | C13: ㈱ホコタ | D13: 2056 | E13: 守谷 | F13: =IFERROR(IF(INDEX(東日本第一ブロック!$J$5:$J$11,MATCH(B13&"|"&C13,東日本第一ブロック!$O$5:$O$11,0))="","未回答",INDEX(東日本第一ブロック!$J$5:$J$11,MATCH(B13&"|"&C13,東日本第一ブロック!$O$5:$O$11,0))),"未回答") -> 未回答 | H13: =IF(G13<>"",G13,F13) -> 未回答 | K13: =IF(OR(J13="",LEFT(H13,1)<>"B"),"",MOD(J13+TIME(1,40,0),1))
A14: 東日本 第一ブロック | B14: 平田 裕治 | C14: ㈱ホコタ | D14: 2152 | E14: 水戸姫子 | F14: =IFERROR(IF(INDEX(東日本第一ブロック!$J$5:$J$11,MATCH(B14&"|"&C14,東日本第一ブロック!$O$5:$O$11,0))="","未回答",INDEX(東日本第一ブロック!$J$5:$J$11,MATCH(B14&"|"&C14,東日本第一ブロック!$O$5:$O$11,0))),"未回答") -> 未回答 | H14: =IF(G14<>"",G14,F14) -> 未回答 | K14: =IF(OR(J14="",LEFT(H14,1)<>"B"),"",MOD(J14+TIME(1,40,0),1))
A15: 東日本 第一ブロック | B15: 平田 裕治 | C15: ㈱ホコタ | D15: 2182 | E15: 水戸南インター | F15: =IFERROR(IF(INDEX(東日本第一ブロック!$J$5:$J$11,MATCH(B15&"|"&C15,東日本第一ブロック!$O$5:$O$11,0))="","未回答",INDEX(東日本第一ブロック!$J$5:$J$11,MATCH(B15&"|"&C15,東日本第一ブロック!$O$5:$O$11,0))),"未回答") -> 未回答 | H15: =IF(G15<>"",G15,F15) -> 未回答 | K15: =IF(OR(J15="",LEFT(H15,1)<>"B"),"",MOD(J15+TIME(1,40,0),1))
A16: 東日本 第一ブロック | B16: 平田 裕治 | C16: ㈱ホコタ | D16: 2262 | E16: 那珂 | F16: =IFERROR(IF(INDEX(東日本第一ブロック!$J$5:$J$11,MATCH(B16&"|"&C16,東日本第一ブロック!$O$5:$O$11,0))="","未回答",INDEX(東日本第一ブロック!$J$5:$J$11,MATCH(B16&"|"&C16,東日本第一ブロック!$O$5:$O$11,0))),"未回答") -> 未回答 | H16: =IF(G16<>"",G16,F16) -> 未回答 | K16: =IF(OR(J16="",LEFT(H16,1)<>"B"),"",MOD(J16+TIME(1,40,0),1))
... A28: 東日本 第一ブロック | B28: 西山 幸大 | C28: ㈱しおさいフーズ | D28: 2259 | E28: 長岡 | F28: =IFERROR(IF(INDEX(東日本第一ブロック!$J$5:$J$11,MATCH(B28&"|"&C28,東日本第一ブロック!$O$5:$O$11,0))="","未回答",INDEX(東日本第一ブロック!$J$5:$J$11,MATCH(B28&"|"&C28,東日本第一ブロック!$O$5:$O$11,0))),"未回答") -> 未回答 | H28: =IF(G28<>"",G28,F28) -> 未回答 | K28: =IF(OR(J28="",LEFT(H28,1)<>"B"),"",MOD(J28+TIME(1,40,0),1))
A29: 東日本 第二ブロック | B29: 片寄 蒼 | C29: ㈱本久 | D29: 2129 | E29: 三郷 | F29: =IFERROR(IF(INDEX(東日本第二ブロック!$J$5:$J$8,MATCH(B29&"|"&C29,東日本第二ブロック!$O$5:$O$8,0))="","未回答",INDEX(東日本第二ブロック!$J$5:$J$8,MATCH(B29&"|"&C29,東日本第二ブロック!$O$5:$O$8,0))),"未回答") -> 未回答 | H29: =IF(G29<>"",G29,F29) -> 未回答 | K29: =IF(OR(J29="",LEFT(H29,1)<>"B"),"",MOD(J29+TIME(1,40,0),1))
A30: 東日本 第二ブロック | B30: 片寄 蒼 | C30: ㈱本久 | D30: 2141 | E30: 太田 | F30: =IFERROR(IF(INDEX(東日本第二ブロック!$J$5:$J$8,MATCH(B30&"|"&C30,東日本第二ブロック!$O$5:$O$8,0))="","未回答",INDEX(東日本第二ブロック!$J$5:$J$8,MATCH(B30&"|"&C30,東日本第二ブロック!$O$5:$O$8,0))),"未回答") -> 未回答 | H30: =IF(G30<>"",G30,F30) -> 未回答 | K30: =IF(OR(J30="",LEFT(H30,1)<>"B"),"",MOD(J30+TIME(1,40,0),1))
A31: 東日本 第二ブロック | B31: 片寄 蒼 | C31: ㈱本久 | D31: 2171 | E31: 春日部 | F31: =IFERROR(IF(INDEX(東日本第二ブロック!$J$5:$J$8,MATCH(B31&"|"&C31,東日本第二ブロック!$O$5:$O$8,0))="","未回答",INDEX(東日本第二ブロック!$J$5:$J$8,MATCH(B31&"|"&C31,東日本第二ブロック!$O$5:$O$8,0))),"未回答") -> 未回答 | H31: =IF(G31<>"",G31,F31) -> 未回答 | K31: =IF(OR(J31="",LEFT(H31,1)<>"B"),"",MOD(J31+TIME(1,40,0),1))
A32: 東日本 第二ブロック | B32: 片寄 蒼 | C32: ㈱本久 | D32: 2176 | E32: 伊勢崎 | F32: =IFERROR(IF(INDEX(東日本第二ブロック!$J$5:$J$8,MATCH(B32&"|"&C32,東日本第二ブロック!$O$5:$O$8,0))="","未回答",INDEX(東日本第二ブロック!$J$5:$J$8,MATCH(B32&"|"&C32,東日本第二ブロック!$O$5:$O$8,0))),"未回答") -> 未回答 | H32: =IF(G32<>"",G32,F32) -> 未回答 | K32: =IF(OR(J32="",LEFT(H32,1)<>"B"),"",MOD(J32+TIME(1,40,0),1))
A33: 東日本 第二ブロック | B33: 片寄 蒼 | C33: ㈱本久 | D33: 2304 | E33: 久喜 | F33: =IFERROR(IF(INDEX(東日本第二ブロック!$J$5:$J$8,MATCH(B33&"|"&C33,東日本第二ブロック!$O$5:$O$8,0))="","未回答",INDEX(東日本第二ブロック!$J$5:$J$8,MATCH(B33&"|"&C33,東日本第二ブロック!$O$5:$O$8,0))),"未回答") -> 未回答 | H33: =IF(G33<>"",G33,F33) -> 未回答 | K33: =IF(OR(J33="",LEFT(H33,1)<>"B"),"",MOD(J33+TIME(1,40,0),1))
A34: 東日本 第二ブロック | B34: 片寄 蒼 | C34: ㈱本久 | D34: 2387 | E34: 羽生 | F34: =IFERROR(IF(INDEX(東日本第二ブロック!$J$5:$J$8,MATCH(B34&"|"&C34,東日本第二ブロック!$O$5:$O$8,0))="","未回答",INDEX(東日本第二ブロック!$J$5:$J$8,MATCH(B34&"|"&C34,東日本第二ブロック!$O$5:$O$8,0))),"未回答") -> 未回答 | H34: =IF(G34<>"",G34,F34) -> 未回答 | K34: =IF(OR(J34="",LEFT(H34,1)<>"B"),"",MOD(J34+TIME(1,40,0),1))
A35: 東日本 第二ブロック | B35: 永田 翔馬 | C35: 株式会社フードフォワード | D35: 2123 | E35: つくば | F35: =IFERROR(IF(INDEX(東日本第二ブロック!$J$5:$J$8,MATCH(B35&"|"&C35,東日本第二ブロック!$O$5:$O$8,0))="","未回答",INDEX(東日本第二ブロック!$J$5:$J$8,MATCH(B35&"|"&C35,東日本第二ブロック!$O$5:$O$8,0))),"未回答") -> 未回答 | H35: =IF(G35<>"",G35,F35) -> 未回答 | K35: =IF(OR(J35="",LEFT(H35,1)<>"B"),"",MOD(J35+TIME(1,40,0),1))
A36: 東日本 第二ブロック | B36: 永田 翔馬 | C36: 株式会社フードフォワード | D36: 2200 | E36: 八千代 | F36: =IFERROR(IF(INDEX(東日本第二ブロック!$J$5:$J$8,MATCH(B36&"|"&C36,東日本第二ブロック!$O$5:$O$8,0))="","未回答",INDEX(東日本第二ブロック!$J$5:$J$8,MATCH(B36&"|"&C36,東日本第二ブロック!$O$5:$O$8,0))),"未回答") -> 未回答 | H36: =IF(G36<>"",G36,F36) -> 未回答 | K36: =IF(OR(J36="",LEFT(H36,1)<>"B"),"",MOD(J36+TIME(1,40,0),1))
A37: 東日本 第二ブロック | B37: 永田 翔馬 | C37: 株式会社フードフォワード | D37: 2300 | E37: 我孫子 | F37: =IFERROR(IF(INDEX(東日本第二ブロック!$J$5:$J$8,MATCH(B37&"|"&C37,東日本第二ブロック!$O$5:$O$8,0))="","未回答",INDEX(東日本第二ブロック!$J$5:$J$8,MATCH(B37&"|"&C37,東日本第二ブロック!$O$5:$O$8,0))),"未回答") -> 未回答 | H37: =IF(G37<>"",G37,F37) -> 未回答 | K37: =IF(OR(J37="",LEFT(H37,1)<>"B"),"",MOD(J37+TIME(1,40,0),1))
A38: 東日本 第二ブロック | B38: 酒井 胤樹 | C38: ノヴィルフォーワード㈱ | D38: 2202 | E38: おゆみ野 | F38: =IFERROR(IF(INDEX(東日本第二ブロック!$J$5:$J$8,MATCH(B38&"|"&C38,東日本第二ブロック!$O$5:$O$8,0))="","未回答",INDEX(東日本第二ブロック!$J$5:$J$8,MATCH(B38&"|"&C38,東日本第二ブロック!$O$5:$O$8,0))),"未回答") -> 未回答 | H38: =IF(G38<>"",G38,F38) -> 未回答 | K38: =IF(OR(J38="",LEFT(H38,1)<>"B"),"",MOD(J38+TIME(1,40,0),1))
A39: 東日本 第二ブロック | B39: 酒井 胤樹 | C39: ノヴィルフォーワード㈱ | D39: 2213 | E39: 鹿嶋 | F39: =IFERROR(IF(INDEX(東日本第二ブロック!$J$5:$J$8,MATCH(B39&"|"&C39,東日本第二ブロック!$O$5:$O$8,0))="","未回答",INDEX(東日本第二ブロック!$J$5:$J$8,MATCH(B39&"|"&C39,東日本第二ブロック!$O$5:$O$8,0))),"未回答") -> 未回答 | H39: =IF(G39<>"",G39,F39) -> 未回答 | K39: =IF(OR(J39="",LEFT(H39,1)<>"B"),"",MOD(J39+TIME(1,40,0),1))
A40: 東日本 第二ブロック | B40: 酒井 胤樹 | C40: ノヴィルフォーワード㈱ | D40: 2230 | E40: 市原五井 | F40: =IFERROR(IF(INDEX(東日本第二ブロック!$J$5:$J$8,MATCH(B40&"|"&C40,東日本第二ブロック!$O$5:$O$8,0))="","未回答",INDEX(東日本第二ブロック!$J$5:$J$8,MATCH(B40&"|"&C40,東日本第二ブロック!$O$5:$O$8,0))),"未回答") -> 未回答 | H40: =IF(G40<>"",G40,F40) -> 未回答 | K40: =IF(OR(J40="",LEFT(H40,1)<>"B"),"",MOD(J40+TIME(1,40,0),1))
... A46: 東日本 第二ブロック | B46: 佐藤 恵介 | C46: ㈱本久 | D46: 2275 | E46: 練馬石神井台 | F46: =IFERROR(IF(INDEX(東日本第二ブロック!$J$5:$J$8,MATCH(B46&"|"&C46,東日本第二ブロック!$O$5:$O$8,0))="","未回答",INDEX(東日本第二ブロック!$J$5:$J$8,MATCH(B46&"|"&C46,東日本第二ブロック!$O$5:$O$8,0))),"未回答") -> 未回答 | H46: =IF(G46<>"",G46,F46) -> 未回答 | K46: =IF(OR(J46="",LEFT(H46,1)<>"B"),"",MOD(J46+TIME(1,40,0),1))
A47: 西日本 第一ブロック | B47: 松山 哲弘 | C47: ㈱本久 | D47: 2204 | E47: 佐久平 | F47: =IFERROR(IF(INDEX(西日本第一ブロック!$J$5:$J$12,MATCH(B47&"|"&C47,西日本第一ブロック!$O$5:$O$12,0))="","未回答",INDEX(西日本第一ブロック!$J$5:$J$12,MATCH(B47&"|"&C47,西日本第一ブロック!$O$5:$O$12,0))),"未回答") -> 未回答 | H47: =IF(G47<>"",G47,F47) -> 未回答 | K47: =IF(OR(J47="",LEFT(H47,1)<>"B"),"",MOD(J47+TIME(1,40,0),1))
A48: 西日本 第一ブロック | B48: 松山 哲弘 | C48: ㈱本久 | D48: 2238 | E48: 上田 | F48: =IFERROR(IF(INDEX(西日本第一ブロック!$J$5:$J$12,MATCH(B48&"|"&C48,西日本第一ブロック!$O$5:$O$12,0))="","未回答",INDEX(西日本第一ブロック!$J$5:$J$12,MATCH(B48&"|"&C48,西日本第一ブロック!$O$5:$O$12,0))),"未回答") -> 未回答 | H48: =IF(G48<>"",G48,F48) -> 未回答 | K48: =IF(OR(J48="",LEFT(H48,1)<>"B"),"",MOD(J48+TIME(1,40,0),1))
A49: 西日本 第一ブロック | B49: 松山 哲弘 | C49: 中信興業㈱ | D49: 2359 | E49: 松本あがた | F49: =IFERROR(IF(INDEX(西日本第一ブロック!$J$5:$J$12,MATCH(B49&"|"&C49,西日本第一ブロック!$O$5:$O$12,0))="","未回答",INDEX(西日本第一ブロック!$J$5:$J$12,MATCH(B49&"|"&C49,西日本第一ブロック!$O$5:$O$12,0))),"未回答") -> 未回答 | H49: =IF(G49<>"",G49,F49) -> 未回答 | K49: =IF(OR(J49="",LEFT(H49,1)<>"B"),"",MOD(J49+TIME(1,40,0),1))
A50: 西日本 第一ブロック | B50: 金 ヨンギョン | C50: 日映㈱ | D50: 2047 | E50: 小黒 | F50: =IFERROR(IF(INDEX(西日本第一ブロック!$J$5:$J$12,MATCH(B50&"|"&C50,西日本第一ブロック!$O$5:$O$12,0))="","未回答",INDEX(西日本第一ブロック!$J$5:$J$12,MATCH(B50&"|"&C50,西日本第一ブロック!$O$5:$O$12,0))),"未回答") -> 未回答 | H50: =IF(G50<>"",G50,F50) -> 未回答 | K50: =IF(OR(J50="",LEFT(H50,1)<>"B"),"",MOD(J50+TIME(1,40,0),1))
A51: 西日本 第一ブロック | B51: 金 ヨンギョン | C51: 日映㈱ | D51: 2319 | E51: 静岡流通通り | F51: =IFERROR(IF(INDEX(西日本第一ブロック!$J$5:$J$12,MATCH(B51&"|"&C51,西日本第一ブロック!$O$5:$O$12,0))="","未回答",INDEX(西日本第一ブロック!$J$5:$J$12,MATCH(B51&"|"&C51,西日本第一ブロック!$O$5:$O$12,0))),"未回答") -> 未回答 | H51: =IF(G51<>"",G51,F51) -> 未回答 | K51: =IF(OR(J51="",LEFT(H51,1)<>"B"),"",MOD(J51+TIME(1,40,0),1))
A52: 西日本 第一ブロック | B52: 金 ヨンギョン | C52: ㈱呉竹荘 | D52: 2281 | E52: 志都呂 | F52: =IFERROR(IF(INDEX(西日本第一ブロック!$J$5:$J$12,MATCH(B52&"|"&C52,西日本第一ブロック!$O$5:$O$12,0))="","未回答",INDEX(西日本第一ブロック!$J$5:$J$12,MATCH(B52&"|"&C52,西日本第一ブロック!$O$5:$O$12,0))),"未回答") -> 未回答 | H52: =IF(G52<>"",G52,F52) -> 未回答 | K52: =IF(OR(J52="",LEFT(H52,1)<>"B"),"",MOD(J52+TIME(1,40,0),1))
A53: 西日本 第一ブロック | B53: 名越 康祐 | C53: 豊田産業㈱ | D53: 2071 | E53: 梅坪 | F53: =IFERROR(IF(INDEX(西日本第一ブロック!$J$5:$J$12,MATCH(B53&"|"&C53,西日本第一ブロック!$O$5:$O$12,0))="","未回答",INDEX(西日本第一ブロック!$J$5:$J$12,MATCH(B53&"|"&C53,西日本第一ブロック!$O$5:$O$12,0))),"未回答") -> 未回答 | H53: =IF(G53<>"",G53,F53) -> 未回答 | K53: =IF(OR(J53="",LEFT(H53,1)<>"B"),"",MOD(J53+TIME(1,40,0),1))
A54: 西日本 第一ブロック | B54: 名越 康祐 | C54: 豊田産業㈱ | D54: 2097 | E54: 豊田浄水 | F54: =IFERROR(IF(INDEX(西日本第一ブロック!$J$5:$J$12,MATCH(B54&"|"&C54,西日本第一ブロック!$O$5:$O$12,0))="","未回答",INDEX(西日本第一ブロック!$J$5:$J$12,MATCH(B54&"|"&C54,西日本第一ブロック!$O$5:$O$12,0))),"未回答") -> 未回答 | H54: =IF(G54<>"",G54,F54) -> 未回答 | K54: =IF(OR(J54="",LEFT(H54,1)<>"B"),"",MOD(J54+TIME(1,40,0),1))
A55: 西日本 第一ブロック | B55: 名越 康祐 | C55: 豊田産業㈱ | D55: 2118 | E55: 三河安城 | F55: =IFERROR(IF(INDEX(西日本第一ブロック!$J$5:$J$12,MATCH(B55&"|"&C55,西日本第一ブロック!$O$5:$O$12,0))="","未回答",INDEX(西日本第一ブロック!$J$5:$J$12,MATCH(B55&"|"&C55,西日本第一ブロック!$O$5:$O$12,0))),"未回答") -> 未回答 | H55: =IF(G55<>"",G55,F55) -> 未回答 | K55: =IF(OR(J55="",LEFT(H55,1)<>"B"),"",MOD(J55+TIME(1,40,0),1))
A56: 西日本 第一ブロック | B56: 名越 康祐 | C56: 豊田産業㈱ | D56: 2161 | E56: 三好 | F56: =IFERROR(IF(INDEX(西日本第一ブロック!$J$5:$J$12,MATCH(B56&"|"&C56,西日本第一ブロック!$O$5:$O$12,0))="","未回答",INDEX(西日本第一ブロック!$J$5:$J$12,MATCH(B56&"|"&C56,西日本第一ブロック!$O$5:$O$12,0))),"未回答") -> 未回答 | H56: =IF(G56<>"",G56,F56) -> 未回答 | K56: =IF(OR(J56="",LEFT(H56,1)<>"B"),"",MOD(J56+TIME(1,40,0),1))
A57: 西日本 第一ブロック | B57: 名越 康祐 | C57: 豊田産業㈱ | D57: 2236 | E57: 西尾 | F57: =IFERROR(IF(INDEX(西日本第一ブロック!$J$5:$J$12,MATCH(B57&"|"&C57,西日本第一ブロック!$O$5:$O$12,0))="","未回答",INDEX(西日本第一ブロック!$J$5:$J$12,MATCH(B57&"|"&C57,西日本第一ブロック!$O$5:$O$12,0))),"未回答") -> 未回答 | H57: =IF(G57<>"",G57,F57) -> 未回答 | K57: =IF(OR(J57="",LEFT(H57,1)<>"B"),"",MOD(J57+TIME(1,40,0),1))
...
