Workbook

Sheet 使い方
B2: 日別客数予測ツール
B4: ■ 毎月の使い方
B5: ① 「先月データ」シートのA1を選択 → 先月の時間帯別売上実績表（見出し行ごと）を貼り付け
B6: ② 「先々月データ」シートのA1に先々月分を貼り付け
B7: ③ （推奨）「前年当月データ」シートのA1に、1年前の当月＋翌月1日（例：当月が2026年10月なら2025/10/1〜11/1）を貼り付け
B8: ※ 貼り付け前に、前回のデータを A〜X 列ごと削除してください（Z列以降の自動計算列は消さない）
B9: ④ 「予測」シートで当月の営業カレンダーを確認。夏休みの平日ランチ営業・臨時休業などは黄色の「営業区分」で指定
B10: ⑤ 必要なら「日別補正」にイベント・天候などの倍率を入力。「時間帯別予測」はシフト作成に使えます
B11: ⑥ 「売上予測貼付用」の F4:M34 をコピー →【事前】売上予測 タブの F4 に「値の貼り付け」（客単価・客数が時間帯別に入ります）
B13: ■ 予測の考え方
B14: 予測客数 ＝ 予測ランチ ＋ 予測ディナー（ランチとディナーを別々に予測して足す）
B15: ・営業区分：「設定」の平日／土日祝のランチ営業（あり・なし）で店舗ごとの標準を決め、日ごとの例外は「予測」シートで指定。ディナーのみの日はランチ分を0にする
... B37: 黄色背景・青字＝入力してよいセル ／ それ以外＝自動計算（触らない）

Sheet 予測
A1: =IF(設定!$B$7="","日別客数予測（先月データを貼り付けてください）",TEXT(設定!$B$7,"yyyy年m月")&" 日別客数予測") -> 日別客数予測（先月データを貼り付けてください）
A2: ="データ: "&設定!$B$36&" ／ 季節係数 "&TEXT(設定!$B$21,"0.000")&" 直近前年比 "&TEXT(設定!$B$22,"0.000")&" トレンド係数 "&TEXT(設定!$B$19,"0.00")&" 前年同曜日の重み "&TEXT(設定!$B$17,"0.00") -> データ: 先月データ未貼付 ／ 季節係数 1.000 直近前年比 1.000 トレンド係数 1.00 前年同曜日の重み 0.50
A3: 月間予測客数 | D3: =SUM(O9:O39) -> 0 | G3: 黄色の列だけ入力します：
A4: 月間予測売上 | D4: =SUM(P9:P39) -> 0 | G4: ・営業区分（変更時のみ）… 通常は空欄＝「設定」のランチ営業あり／なしに従う。夏休みの平日ランチ営業・臨時休業などはここで指定
A5: 先月実績客数 | D5: =SUM(集計!$E$3:$E$33) -> 0 | G5: ・日別補正 … イベント・天候・販促などの倍率（例：雨予報0.9、地域祭り1.2）
A6: 先月比(客数) | D6: =IFERROR(D3/D5,"")
A7: 予測客単価 | D7: =IFERROR(D4/D3,"")
A8: 日付 | B8: 曜日 | C8: 日タイプ | D8: 営業区分 (変更時のみ) | E8: 適用 営業区分 | F8: ランチ 基準 | G8: ディナー 基準 | H8: 前年 同曜日 | I8: 前年 客数 | J8: 季節 係数 | K8: トレンド 係数 | L8: 日別 補正 | M8: 予測 ランチ | N8: 予測 ディナー | O8: 予測客数 | P8: 予測売上 | Q8: 予測 客単価 | R8: メモ | T8: (計算用)前年ランチ | U8: (計算用)前年ディナー | V8: (計算用)前年タイプ | W8: (計算用)前年を使う
A9: =IF(OR(設定!$B$7="",1>設定!$B$8),"",設定!$B$7+0) | B9: =IF($A9="","",CHOOSE(WEEKDAY($A9,2),"月","火","水","木","金","土","日")) | C9: =IF($A9="","",IF(COUNTIF(祝日!$A:$A,$A9)>0,"祝",CHOOSE(WEEKDAY($A9,2),"月","火","水","木","金","土","日"))) | E9: =IF($A9="","",IF(D9<>"",D9,IF(IF(OR(C9="土",C9="日",C9="祝"),設定!$B$12,設定!$B$11)="あり","ランチ+ディナー","ディナーのみ"))) | F9: =IF($A9="","",IF(E9="ランチ+ディナー",INDEX(集計!$M$38:$M$45,MATCH(C9,集計!$A$38:$A$45,0)),0)) | G9: =IF($A9="","",IF(E9="休業",0,INDEX(集計!$L$38:$L$45,MATCH(C9,集計!$A$38:$A$45,0)))) | H9: =IF(W9=1,$A9-364,"") | I9: =IF(W9=1,IF(AND(E9="ランチ+ディナー",T9>=設定!$B$13),T9,0)+U9,"") | J9: =IF($A9="","",設定!$B$21) | K9: =IF($A9="","",設定!$B$19) | L9: 1 | M9: =IF($A9="","",IF(E9<>"ランチ+ディナー",0,IF(AND(W9=1,T9>=設定!$B$13),(1-設定!$B$17)*F9*J9+設定!$B$17*T9*設定!$B$22,F9*J9)*K9*N(L9))) | N9: =IF($A9="","",IF(E9="休業",0,IF(W9=1,(1-設定!$B$17)*G9*J9+設定!$B$17*U9*設定!$B$22,G9*J9)*K9*N(L9))) | O9: =IF($A9="","",ROUND(M9+N9,0)) | P9: =IF($A9="","",売上予測貼付用!S4) | Q9: =IF($A9="","",IFERROR(P9/O9,"")) | T9: =IF($A9="","",IF(COUNTIF(前年当月データ!$A:$A,$A9-364)=0,"",SUMIFS(前年当月データ!$Q:$Q,前年当月データ!$A:$A,$A9-364,前年当月データ!$K:$K,">=6",前年当月データ!$K:$K,"<"&設定!$B$10))) | U9: =IF(T9="","",SUMIFS(前年当月データ!$Q:$Q,前年当月データ!$A:$A,$A9-364)-T9) | V9: =IF(T9="","",IF(COUNTIF(祝日!$A:$A,($A9-364))>0,"祝",CHOOSE(WEEKDAY(($A9-364),2),"月","火","水","木","金","土","日"))) | W9: =IF($A9="",0,IF(AND(設定!$B$17>0,N(U9)>0,C9<>"祝",V9<>"祝",E9<>"休業"),1,0)) -> 0
A10: =IF(OR(設定!$B$7="",2>設定!$B$8),"",設定!$B$7+1) | B10: =IF($A10="","",CHOOSE(WEEKDAY($A10,2),"月","火","水","木","金","土","日")) | C10: =IF($A10="","",IF(COUNTIF(祝日!$A:$A,$A10)>0,"祝",CHOOSE(WEEKDAY($A10,2),"月","火","水","木","金","土","日"))) | E10: =IF($A10="","",IF(D10<>"",D10,IF(IF(OR(C10="土",C10="日",C10="祝"),設定!$B$12,設定!$B$11)="あり","ランチ+ディナー","ディナーのみ"))) | F10: =IF($A10="","",IF(E10="ランチ+ディナー",INDEX(集計!$M$38:$M$45,MATCH(C10,集計!$A$38:$A$45,0)),0)) | G10: =IF($A10="","",IF(E10="休業",0,INDEX(集計!$L$38:$L$45,MATCH(C10,集計!$A$38:$A$45,0)))) | H10: =IF(W10=1,$A10-364,"") | I10: =IF(W10=1,IF(AND(E10="ランチ+ディナー",T10>=設定!$B$13),T10,0)+U10,"") | J10: =IF($A10="","",設定!$B$21) | K10: =IF($A10="","",設定!$B$19) | L10: 1 | M10: =IF($A10="","",IF(E10<>"ランチ+ディナー",0,IF(AND(W10=1,T10>=設定!$B$13),(1-設定!$B$17)*F10*J10+設定!$B$17*T10*設定!$B$22,F10*J10)*K10*N(L10))) | N10: =IF($A10="","",IF(E10="休業",0,IF(W10=1,(1-設定!$B$17)*G10*J10+設定!$B$17*U10*設定!$B$22,G10*J10)*K10*N(L10))) | O10: =IF($A10="","",ROUND(M10+N10,0)) | P10: =IF($A10="","",売上予測貼付用!S5) | Q10: =IF($A10="","",IFERROR(P10/O10,"")) | T10: =IF($A10="","",IF(COUNTIF(前年当月データ!$A:$A,$A10-364)=0,"",SUMIFS(前年当月データ!$Q:$Q,前年当月データ!$A:$A,$A10-364,前年当月データ!$K:$K,">=6",前年当月データ!$K:$K,"<"&設定!$B$10))) | U10: =IF(T10="","",SUMIFS(前年当月データ!$Q:$Q,前年当月データ!$A:$A,$A10-364)-T10) | V10: =IF(T10="","",IF(COUNTIF(祝日!$A:$A,($A10-364))>0,"祝",CHOOSE(WEEKDAY(($A10-364),2),"月","火","水","木","金","土","日"))) | W10: =IF($A10="",0,IF(AND(設定!$B$17>0,N(U10)>0,C10<>"祝",V10<>"祝",E10<>"休業"),1,0)) -> 0
A11: =IF(OR(設定!$B$7="",3>設定!$B$8),"",設定!$B$7+2) | B11: =IF($A11="","",CHOOSE(WEEKDAY($A11,2),"月","火","水","木","金","土","日")) | C11: =IF($A11="","",IF(COUNTIF(祝日!$A:$A,$A11)>0,"祝",CHOOSE(WEEKDAY($A11,2),"月","火","水","木","金","土","日"))) | E11: =IF($A11="","",IF(D11<>"",D11,IF(IF(OR(C11="土",C11="日",C11="祝"),設定!$B$12,設定!$B$11)="あり","ランチ+ディナー","ディナーのみ"))) | F11: =IF($A11="","",IF(E11="ランチ+ディナー",INDEX(集計!$M$38:$M$45,MATCH(C11,集計!$A$38:$A$45,0)),0)) | G11: =IF($A11="","",IF(E11="休業",0,INDEX(集計!$L$38:$L$45,MATCH(C11,集計!$A$38:$A$45,0)))) | H11: =IF(W11=1,$A11-364,"") | I11: =IF(W11=1,IF(AND(E11="ランチ+ディナー",T11>=設定!$B$13),T11,0)+U11,"") | J11: =IF($A11="","",設定!$B$21) | K11: =IF($A11="","",設定!$B$19) | L11: 1 | M11: =IF($A11="","",IF(E11<>"ランチ+ディナー",0,IF(AND(W11=1,T11>=設定!$B$13),(1-設定!$B$17)*F11*J11+設定!$B$17*T11*設定!$B$22,F11*J11)*K11*N(L11))) | N11: =IF($A11="","",IF(E11="休業",0,IF(W11=1,(1-設定!$B$17)*G11*J11+設定!$B$17*U11*設定!$B$22,G11*J11)*K11*N(L11))) | O11: =IF($A11="","",ROUND(M11+N11,0)) | P11: =IF($A11="","",売上予測貼付用!S6) | Q11: =IF($A11="","",IFERROR(P11/O11,"")) | T11: =IF($A11="","",IF(COUNTIF(前年当月データ!$A:$A,$A11-364)=0,"",SUMIFS(前年当月データ!$Q:$Q,前年当月データ!$A:$A,$A11-364,前年当月データ!$K:$K,">=6",前年当月データ!$K:$K,"<"&設定!$B$10))) | U11: =IF(T11="","",SUMIFS(前年当月データ!$Q:$Q,前年当月データ!$A:$A,$A11-364)-T11) | V11: =IF(T11="","",IF(COUNTIF(祝日!$A:$A,($A11-364))>0,"祝",CHOOSE(WEEKDAY(($A11-364),2),"月","火","水","木","金","土","日"))) | W11: =IF($A11="",0,IF(AND(設定!$B$17>0,N(U11)>0,C11<>"祝",V11<>"祝",E11<>"休業"),1,0)) -> 0
A12: =IF(OR(設定!$B$7="",4>設定!$B$8),"",設定!$B$7+3) | B12: =IF($A12="","",CHOOSE(WEEKDAY($A12,2),"月","火","水","木","金","土","日")) | C12: =IF($A12="","",IF(COUNTIF(祝日!$A:$A,$A12)>0,"祝",CHOOSE(WEEKDAY($A12,2),"月","火","水","木","金","土","日"))) | E12: =IF($A12="","",IF(D12<>"",D12,IF(IF(OR(C12="土",C12="日",C12="祝"),設定!$B$12,設定!$B$11)="あり","ランチ+ディナー","ディナーのみ"))) | F12: =IF($A12="","",IF(E12="ランチ+ディナー",INDEX(集計!$M$38:$M$45,MATCH(C12,集計!$A$38:$A$45,0)),0)) | G12: =IF($A12="","",IF(E12="休業",0,INDEX(集計!$L$38:$L$45,MATCH(C12,集計!$A$38:$A$45,0)))) | H12: =IF(W12=1,$A12-364,"") | I12: =IF(W12=1,IF(AND(E12="ランチ+ディナー",T12>=設定!$B$13),T12,0)+U12,"") | J12: =IF($A12="","",設定!$B$21) | K12: =IF($A12="","",設定!$B$19) | L12: 1 | M12: =IF($A12="","",IF(E12<>"ランチ+ディナー",0,IF(AND(W12=1,T12>=設定!$B$13),(1-設定!$B$17)*F12*J12+設定!$B$17*T12*設定!$B$22,F12*J12)*K12*N(L12))) | N12: =IF($A12="","",IF(E12="休業",0,IF(W12=1,(1-設定!$B$17)*G12*J12+設定!$B$17*U12*設定!$B$22,G12*J12)*K12*N(L12))) | O12: =IF($A12="","",ROUND(M12+N12,0)) | P12: =IF($A12="","",売上予測貼付用!S7) | Q12: =IF($A12="","",IFERROR(P12/O12,"")) | T12: =IF($A12="","",IF(COUNTIF(前年当月データ!$A:$A,$A12-364)=0,"",SUMIFS(前年当月データ!$Q:$Q,前年当月データ!$A:$A,$A12-364,前年当月データ!$K:$K,">=6",前年当月データ!$K:$K,"<"&設定!$B$10))) | U12: =IF(T12="","",SUMIFS(前年当月データ!$Q:$Q,前年当月データ!$A:$A,$A12-364)-T12) | V12: =IF(T12="","",IF(COUNTIF(祝日!$A:$A,($A12-364))>0,"祝",CHOOSE(WEEKDAY(($A12-364),2),"月","火","水","木","金","土","日"))) | W12: =IF($A12="",0,IF(AND(設定!$B$17>0,N(U12)>0,C12<>"祝",V12<>"祝",E12<>"休業"),1,0)) -> 0
A13: =IF(OR(設定!$B$7="",5>設定!$B$8),"",設定!$B$7+4) | B13: =IF($A13="","",CHOOSE(WEEKDAY($A13,2),"月","火","水","木","金","土","日")) | C13: =IF($A13="","",IF(COUNTIF(祝日!$A:$A,$A13)>0,"祝",CHOOSE(WEEKDAY($A13,2),"月","火","水","木","金","土","日"))) | E13: =IF($A13="","",IF(D13<>"",D13,IF(IF(OR(C13="土",C13="日",C13="祝"),設定!$B$12,設定!$B$11)="あり","ランチ+ディナー","ディナーのみ"))) | F13: =IF($A13="","",IF(E13="ランチ+ディナー",INDEX(集計!$M$38:$M$45,MATCH(C13,集計!$A$38:$A$45,0)),0)) | G13: =IF($A13="","",IF(E13="休業",0,INDEX(集計!$L$38:$L$45,MATCH(C13,集計!$A$38:$A$45,0)))) | H13: =IF(W13=1,$A13-364,"") | I13: =IF(W13=1,IF(AND(E13="ランチ+ディナー",T13>=設定!$B$13),T13,0)+U13,"") | J13: =IF($A13="","",設定!$B$21) | K13: =IF($A13="","",設定!$B$19) | L13: 1 | M13: =IF($A13="","",IF(E13<>"ランチ+ディナー",0,IF(AND(W13=1,T13>=設定!$B$13),(1-設定!$B$17)*F13*J13+設定!$B$17*T13*設定!$B$22,F13*J13)*K13*N(L13))) | N13: =IF($A13="","",IF(E13="休業",0,IF(W13=1,(1-設定!$B$17)*G13*J13+設定!$B$17*U13*設定!$B$22,G13*J13)*K13*N(L13))) | O13: =IF($A13="","",ROUND(M13+N13,0)) | P13: =IF($A13="","",売上予測貼付用!S8) | Q13: =IF($A13="","",IFERROR(P13/O13,"")) | T13: =IF($A13="","",IF(COUNTIF(前年当月データ!$A:$A,$A13-364)=0,"",SUMIFS(前年当月データ!$Q:$Q,前年当月データ!$A:$A,$A13-364,前年当月データ!$K:$K,">=6",前年当月データ!$K:$K,"<"&設定!$B$10))) | U13: =IF(T13="","",SUMIFS(前年当月データ!$Q:$Q,前年当月データ!$A:$A,$A13-364)-T13) | V13: =IF(T13="","",IF(COUNTIF(祝日!$A:$A,($A13-364))>0,"祝",CHOOSE(WEEKDAY(($A13-364),2),"月","火","水","木","金","土","日"))) | W13: =IF($A13="",0,IF(AND(設定!$B$17>0,N(U13)>0,C13<>"祝",V13<>"祝",E13<>"休業"),1,0)) -> 0
A14: =IF(OR(設定!$B$7="",6>設定!$B$8),"",設定!$B$7+5) | B14: =IF($A14="","",CHOOSE(WEEKDAY($A14,2),"月","火","水","木","金","土","日")) | C14: =IF($A14="","",IF(COUNTIF(祝日!$A:$A,$A14)>0,"祝",CHOOSE(WEEKDAY($A14,2),"月","火","水","木","金","土","日"))) | E14: =IF($A14="","",IF(D14<>"",D14,IF(IF(OR(C14="土",C14="日",C14="祝"),設定!$B$12,設定!$B$11)="あり","ランチ+ディナー","ディナーのみ"))) | F14: =IF($A14="","",IF(E14="ランチ+ディナー",INDEX(集計!$M$38:$M$45,MATCH(C14,集計!$A$38:$A$45,0)),0)) | G14: =IF($A14="","",IF(E14="休業",0,INDEX(集計!$L$38:$L$45,MATCH(C14,集計!$A$38:$A$45,0)))) | H14: =IF(W14=1,$A14-364,"") | I14: =IF(W14=1,IF(AND(E14="ランチ+ディナー",T14>=設定!$B$13),T14,0)+U14,"") | J14: =IF($A14="","",設定!$B$21) | K14: =IF($A14="","",設定!$B$19) | L14: 1 | M14: =IF($A14="","",IF(E14<>"ランチ+ディナー",0,IF(AND(W14=1,T14>=設定!$B$13),(1-設定!$B$17)*F14*J14+設定!$B$17*T14*設定!$B$22,F14*J14)*K14*N(L14))) | N14: =IF($A14="","",IF(E14="休業",0,IF(W14=1,(1-設定!$B$17)*G14*J14+設定!$B$17*U14*設定!$B$22,G14*J14)*K14*N(L14))) | O14: =IF($A14="","",ROUND(M14+N14,0)) | P14: =IF($A14="","",売上予測貼付用!S9) | Q14: =IF($A14="","",IFERROR(P14/O14,"")) | T14: =IF($A14="","",IF(COUNTIF(前年当月データ!$A:$A,$A14-364)=0,"",SUMIFS(前年当月データ!$Q:$Q,前年当月データ!$A:$A,$A14-364,前年当月データ!$K:$K,">=6",前年当月データ!$K:$K,"<"&設定!$B$10))) | U14: =IF(T14="","",SUMIFS(前年当月データ!$Q:$Q,前年当月データ!$A:$A,$A14-364)-T14) | V14: =IF(T14="","",IF(COUNTIF(祝日!$A:$A,($A14-364))>0,"祝",CHOOSE(WEEKDAY(($A14-364),2),"月","火","水","木","金","土","日"))) | W14: =IF($A14="",0,IF(AND(設定!$B$17>0,N(U14)>0,C14<>"祝",V14<>"祝",E14<>"休業"),1,0)) -> 0
A15: =IF(OR(設定!$B$7="",7>設定!$B$8),"",設定!$B$7+6) | B15: =IF($A15="","",CHOOSE(WEEKDAY($A15,2),"月","火","水","木","金","土","日")) | C15: =IF($A15="","",IF(COUNTIF(祝日!$A:$A,$A15)>0,"祝",CHOOSE(WEEKDAY($A15,2),"月","火","水","木","金","土","日"))) | E15: =IF($A15="","",IF(D15<>"",D15,IF(IF(OR(C15="土",C15="日",C15="祝"),設定!$B$12,設定!$B$11)="あり","ランチ+ディナー","ディナーのみ"))) | F15: =IF($A15="","",IF(E15="ランチ+ディナー",INDEX(集計!$M$38:$M$45,MATCH(C15,集計!$A$38:$A$45,0)),0)) | G15: =IF($A15="","",IF(E15="休業",0,INDEX(集計!$L$38:$L$45,MATCH(C15,集計!$A$38:$A$45,0)))) | H15: =IF(W15=1,$A15-364,"") | I15: =IF(W15=1,IF(AND(E15="ランチ+ディナー",T15>=設定!$B$13),T15,0)+U15,"") | J15: =IF($A15="","",設定!$B$21) | K15: =IF($A15="","",設定!$B$19) | L15: 1 | M15: =IF($A15="","",IF(E15<>"ランチ+ディナー",0,IF(AND(W15=1,T15>=設定!$B$13),(1-設定!$B$17)*F15*J15+設定!$B$17*T15*設定!$B$22,F15*J15)*K15*N(L15))) | N15: =IF($A15="","",IF(E15="休業",0,IF(W15=1,(1-設定!$B$17)*G15*J15+設定!$B$17*U15*設定!$B$22,G15*J15)*K15*N(L15))) | O15: =IF($A15="","",ROUND(M15+N15,0)) | P15: =IF($A15="","",売上予測貼付用!S10) | Q15: =IF($A15="","",IFERROR(P15/O15,"")) | T15: =IF($A15="","",IF(COUNTIF(前年当月データ!$A:$A,$A15-364)=0,"",SUMIFS(前年当月データ!$Q:$Q,前年当月データ!$A:$A,$A15-364,前年当月データ!$K:$K,">=6",前年当月データ!$K:$K,"<"&設定!$B$10))) | U15: =IF(T15="","",SUMIFS(前年当月データ!$Q:$Q,前年当月データ!$A:$A,$A15-364)-T15) | V15: =IF(T15="","",IF(COUNTIF(祝日!$A:$A,($A15-364))>0,"祝",CHOOSE(WEEKDAY(($A15-364),2),"月","火","水","木","金","土","日"))) | W15: =IF($A15="",0,IF(AND(設定!$B$17>0,N(U15)>0,C15<>"祝",V15<>"祝",E15<>"休業"),1,0)) -> 0
A16: =IF(OR(設定!$B$7="",8>設定!$B$8),"",設定!$B$7+7) | B16: =IF($A16="","",CHOOSE(WEEKDAY($A16,2),"月","火","水","木","金","土","日")) | C16: =IF($A16="","",IF(COUNTIF(祝日!$A:$A,$A16)>0,"祝",CHOOSE(WEEKDAY($A16,2),"月","火","水","木","金","土","日"))) | E16: =IF($A16="","",IF(D16<>"",D16,IF(IF(OR(C16="土",C16="日",C16="祝"),設定!$B$12,設定!$B$11)="あり","ランチ+ディナー","ディナーのみ"))) | F16: =IF($A16="","",IF(E16="ランチ+ディナー",INDEX(集計!$M$38:$M$45,MATCH(C16,集計!$A$38:$A$45,0)),0)) | G16: =IF($A16="","",IF(E16="休業",0,INDEX(集計!$L$38:$L$45,MATCH(C16,集計!$A$38:$A$45,0)))) | H16: =IF(W16=1,$A16-364,"") | I16: =IF(W16=1,IF(AND(E16="ランチ+ディナー",T16>=設定!$B$13),T16,0)+U16,"") | J16: =IF($A16="","",設定!$B$21) | K16: =IF($A16="","",設定!$B$19) | L16: 1 | M16: =IF($A16="","",IF(E16<>"ランチ+ディナー",0,IF(AND(W16=1,T16>=設定!$B$13),(1-設定!$B$17)*F16*J16+設定!$B$17*T16*設定!$B$22,F16*J16)*K16*N(L16))) | N16: =IF($A16="","",IF(E16="休業",0,IF(W16=1,(1-設定!$B$17)*G16*J16+設定!$B$17*U16*設定!$B$22,G16*J16)*K16*N(L16))) | O16: =IF($A16="","",ROUND(M16+N16,0)) | P16: =IF($A16="","",売上予測貼付用!S11) | Q16: =IF($A16="","",IFERROR(P16/O16,"")) | T16: =IF($A16="","",IF(COUNTIF(前年当月データ!$A:$A,$A16-364)=0,"",SUMIFS(前年当月データ!$Q:$Q,前年当月データ!$A:$A,$A16-364,前年当月データ!$K:$K,">=6",前年当月データ!$K:$K,"<"&設定!$B$10))) | U16: =IF(T16="","",SUMIFS(前年当月データ!$Q:$Q,前年当月データ!$A:$A,$A16-364)-T16) | V16: =IF(T16="","",IF(COUNTIF(祝日!$A:$A,($A16-364))>0,"祝",CHOOSE(WEEKDAY(($A16-364),2),"月","火","水","木","金","土","日"))) | W16: =IF($A16="",0,IF(AND(設定!$B$17>0,N(U16)>0,C16<>"祝",V16<>"祝",E16<>"休業"),1,0)) -> 0
A17: =IF(OR(設定!$B$7="",9>設定!$B$8),"",設定!$B$7+8) | B17: =IF($A17="","",CHOOSE(WEEKDAY($A17,2),"月","火","水","木","金","土","日")) | C17: =IF($A17="","",IF(COUNTIF(祝日!$A:$A,$A17)>0,"祝",CHOOSE(WEEKDAY($A17,2),"月","火","水","木","金","土","日"))) | E17: =IF($A17="","",IF(D17<>"",D17,IF(IF(OR(C17="土",C17="日",C17="祝"),設定!$B$12,設定!$B$11)="あり","ランチ+ディナー","ディナーのみ"))) | F17: =IF($A17="","",IF(E17="ランチ+ディナー",INDEX(集計!$M$38:$M$45,MATCH(C17,集計!$A$38:$A$45,0)),0)) | G17: =IF($A17="","",IF(E17="休業",0,INDEX(集計!$L$38:$L$45,MATCH(C17,集計!$A$38:$A$45,0)))) | H17: =IF(W17=1,$A17-364,"") | I17: =IF(W17=1,IF(AND(E17="ランチ+ディナー",T17>=設定!$B$13),T17,0)+U17,"") | J17: =IF($A17="","",設定!$B$21) | K17: =IF($A17="","",設定!$B$19) | L17: 1 | M17: =IF($A17="","",IF(E17<>"ランチ+ディナー",0,IF(AND(W17=1,T17>=設定!$B$13),(1-設定!$B$17)*F17*J17+設定!$B$17*T17*設定!$B$22,F17*J17)*K17*N(L17))) | N17: =IF($A17="","",IF(E17="休業",0,IF(W17=1,(1-設定!$B$17)*G17*J17+設定!$B$17*U17*設定!$B$22,G17*J17)*K17*N(L17))) | O17: =IF($A17="","",ROUND(M17+N17,0)) | P17: =IF($A17="","",売上予測貼付用!S12) | Q17: =IF($A17="","",IFERROR(P17/O17,"")) | T17: =IF($A17="","",IF(COUNTIF(前年当月データ!$A:$A,$A17-364)=0,"",SUMIFS(前年当月データ!$Q:$Q,前年当月データ!$A:$A,$A17-364,前年当月データ!$K:$K,">=6",前年当月データ!$K:$K,"<"&設定!$B$10))) | U17: =IF(T17="","",SUMIFS(前年当月データ!$Q:$Q,前年当月データ!$A:$A,$A17-364)-T17) | V17: =IF(T17="","",IF(COUNTIF(祝日!$A:$A,($A17-364))>0,"祝",CHOOSE(WEEKDAY(($A17-364),2),"月","火","水","木","金","土","日"))) | W17: =IF($A17="",0,IF(AND(設定!$B$17>0,N(U17)>0,C17<>"祝",V17<>"祝",E17<>"休業"),1,0)) -> 0
A18: =IF(OR(設定!$B$7="",10>設定!$B$8),"",設定!$B$7+9) | B18: =IF($A18="","",CHOOSE(WEEKDAY($A18,2),"月","火","水","木","金","土","日")) | C18: =IF($A18="","",IF(COUNTIF(祝日!$A:$A,$A18)>0,"祝",CHOOSE(WEEKDAY($A18,2),"月","火","水","木","金","土","日"))) | E18: =IF($A18="","",IF(D18<>"",D18,IF(IF(OR(C18="土",C18="日",C18="祝"),設定!$B$12,設定!$B$11)="あり","ランチ+ディナー","ディナーのみ"))) | F18: =IF($A18="","",IF(E18="ランチ+ディナー",INDEX(集計!$M$38:$M$45,MATCH(C18,集計!$A$38:$A$45,0)),0)) | G18: =IF($A18="","",IF(E18="休業",0,INDEX(集計!$L$38:$L$45,MATCH(C18,集計!$A$38:$A$45,0)))) | H18: =IF(W18=1,$A18-364,"") | I18: =IF(W18=1,IF(AND(E18="ランチ+ディナー",T18>=設定!$B$13),T18,0)+U18,"") | J18: =IF($A18="","",設定!$B$21) | K18: =IF($A18="","",設定!$B$19) | L18: 1 | M18: =IF($A18="","",IF(E18<>"ランチ+ディナー",0,IF(AND(W18=1,T18>=設定!$B$13),(1-設定!$B$17)*F18*J18+設定!$B$17*T18*設定!$B$22,F18*J18)*K18*N(L18))) | N18: =IF($A18="","",IF(E18="休業",0,IF(W18=1,(1-設定!$B$17)*G18*J18+設定!$B$17*U18*設定!$B$22,G18*J18)*K18*N(L18))) | O18: =IF($A18="","",ROUND(M18+N18,0)) | P18: =IF($A18="","",売上予測貼付用!S13) | Q18: =IF($A18="","",IFERROR(P18/O18,"")) | T18: =IF($A18="","",IF(COUNTIF(前年当月データ!$A:$A,$A18-364)=0,"",SUMIFS(前年当月データ!$Q:$Q,前年当月データ!$A:$A,$A18-364,前年当月データ!$K:$K,">=6",前年当月データ!$K:$K,"<"&設定!$B$10))) | U18: =IF(T18="","",SUMIFS(前年当月データ!$Q:$Q,前年当月データ!$A:$A,$A18-364)-T18) | V18: =IF(T18="","",IF(COUNTIF(祝日!$A:$A,($A18-364))>0,"祝",CHOOSE(WEEKDAY(($A18-364),2),"月","火","水","木","金","土","日"))) | W18: =IF($A18="",0,IF(AND(設定!$B$17>0,N(U18)>0,C18<>"祝",V18<>"祝",E18<>"休業"),1,0)) -> 0
A19: =IF(OR(設定!$B$7="",11>設定!$B$8),"",設定!$B$7+10) | B19: =IF($A19="","",CHOOSE(WEEKDAY($A19,2),"月","火","水","木","金","土","日")) | C19: =IF($A19="","",IF(COUNTIF(祝日!$A:$A,$A19)>0,"祝",CHOOSE(WEEKDAY($A19,2),"月","火","水","木","金","土","日"))) | E19: =IF($A19="","",IF(D19<>"",D19,IF(IF(OR(C19="土",C19="日",C19="祝"),設定!$B$12,設定!$B$11)="あり","ランチ+ディナー","ディナーのみ"))) | F19: =IF($A19="","",IF(E19="ランチ+ディナー",INDEX(集計!$M$38:$M$45,MATCH(C19,集計!$A$38:$A$45,0)),0)) | G19: =IF($A19="","",IF(E19="休業",0,INDEX(集計!$L$38:$L$45,MATCH(C19,集計!$A$38:$A$45,0)))) | H19: =IF(W19=1,$A19-364,"") | I19: =IF(W19=1,IF(AND(E19="ランチ+ディナー",T19>=設定!$B$13),T19,0)+U19,"") | J19: =IF($A19="","",設定!$B$21) | K19: =IF($A19="","",設定!$B$19) | L19: 1 | M19: =IF($A19="","",IF(E19<>"ランチ+ディナー",0,IF(AND(W19=1,T19>=設定!$B$13),(1-設定!$B$17)*F19*J19+設定!$B$17*T19*設定!$B$22,F19*J19)*K19*N(L19))) | N19: =IF($A19="","",IF(E19="休業",0,IF(W19=1,(1-設定!$B$17)*G19*J19+設定!$B$17*U19*設定!$B$22,G19*J19)*K19*N(L19))) | O19: =IF($A19="","",ROUND(M19+N19,0)) | P19: =IF($A19="","",売上予測貼付用!S14) | Q19: =IF($A19="","",IFERROR(P19/O19,"")) | T19: =IF($A19="","",IF(COUNTIF(前年当月データ!$A:$A,$A19-364)=0,"",SUMIFS(前年当月データ!$Q:$Q,前年当月データ!$A:$A,$A19-364,前年当月データ!$K:$K,">=6",前年当月データ!$K:$K,"<"&設定!$B$10))) | U19: =IF(T19="","",SUMIFS(前年当月データ!$Q:$Q,前年当月データ!$A:$A,$A19-364)-T19) | V19: =IF(T19="","",IF(COUNTIF(祝日!$A:$A,($A19-364))>0,"祝",CHOOSE(WEEKDAY(($A19-364),2),"月","火","水","木","金","土","日"))) | W19: =IF($A19="",0,IF(AND(設定!$B$17>0,N(U19)>0,C19<>"祝",V19<>"祝",E19<>"休業"),1,0)) -> 0
A20: =IF(OR(設定!$B$7="",12>設定!$B$8),"",設定!$B$7+11) | B20: =IF($A20="","",CHOOSE(WEEKDAY($A20,2),"月","火","水","木","金","土","日")) | C20: =IF($A20="","",IF(COUNTIF(祝日!$A:$A,$A20)>0,"祝",CHOOSE(WEEKDAY($A20,2),"月","火","水","木","金","土","日"))) | E20: =IF($A20="","",IF(D20<>"",D20,IF(IF(OR(C20="土",C20="日",C20="祝"),設定!$B$12,設定!$B$11)="あり","ランチ+ディナー","ディナーのみ"))) | F20: =IF($A20="","",IF(E20="ランチ+ディナー",INDEX(集計!$M$38:$M$45,MATCH(C20,集計!$A$38:$A$45,0)),0)) | G20: =IF($A20="","",IF(E20="休業",0,INDEX(集計!$L$38:$L$45,MATCH(C20,集計!$A$38:$A$45,0)))) | H20: =IF(W20=1,$A20-364,"") | I20: =IF(W20=1,IF(AND(E20="ランチ+ディナー",T20>=設定!$B$13),T20,0)+U20,"") | J20: =IF($A20="","",設定!$B$21) | K20: =IF($A20="","",設定!$B$19) | L20: 1 | M20: =IF($A20="","",IF(E20<>"ランチ+ディナー",0,IF(AND(W20=1,T20>=設定!$B$13),(1-設定!$B$17)*F20*J20+設定!$B$17*T20*設定!$B$22,F20*J20)*K20*N(L20))) | N20: =IF($A20="","",IF(E20="休業",0,IF(W20=1,(1-設定!$B$17)*G20*J20+設定!$B$17*U20*設定!$B$22,G20*J20)*K20*N(L20))) | O20: =IF($A20="","",ROUND(M20+N20,0)) | P20: =IF($A20="","",売上予測貼付用!S15) | Q20: =IF($A20="","",IFERROR(P20/O20,"")) | T20: =IF($A20="","",IF(COUNTIF(前年当月データ!$A:$A,$A20-364)=0,"",SUMIFS(前年当月データ!$Q:$Q,前年当月データ!$A:$A,$A20-364,前年当月データ!$K:$K,">=6",前年当月データ!$K:$K,"<"&設定!$B$10))) | U20: =IF(T20="","",SUMIFS(前年当月データ!$Q:$Q,前年当月データ!$A:$A,$A20-364)-T20) | V20: =IF(T20="","",IF(COUNTIF(祝日!$A:$A,($A20-364))>0,"祝",CHOOSE(WEEKDAY(($A20-364),2),"月","火","水","木","金","土","日"))) | W20: =IF($A20="",0,IF(AND(設定!$B$17>0,N(U20)>0,C20<>"祝",V20<>"祝",E20<>"休業"),1,0)) -> 0
A21: =IF(OR(設定!$B$7="",13>設定!$B$8),"",設定!$B$7+12) | B21: =IF($A21="","",CHOOSE(WEEKDAY($A21,2),"月","火","水","木","金","土","日")) | C21: =IF($A21="","",IF(COUNTIF(祝日!$A:$A,$A21)>0,"祝",CHOOSE(WEEKDAY($A21,2),"月","火","水","木","金","土","日"))) | E21: =IF($A21="","",IF(D21<>"",D21,IF(IF(OR(C21="土",C21="日",C21="祝"),設定!$B$12,設定!$B$11)="あり","ランチ+ディナー","ディナーのみ"))) | F21: =IF($A21="","",IF(E21="ランチ+ディナー",INDEX(集計!$M$38:$M$45,MATCH(C21,集計!$A$38:$A$45,0)),0)) | G21: =IF($A21="","",IF(E21="休業",0,INDEX(集計!$L$38:$L$45,MATCH(C21,集計!$A$38:$A$45,0)))) | H21: =IF(W21=1,$A21-364,"") | I21: =IF(W21=1,IF(AND(E21="ランチ+ディナー",T21>=設定!$B$13),T21,0)+U21,"") | J21: =IF($A21="","",設定!$B$21) | K21: =IF($A21="","",設定!$B$19) | L21: 1 | M21: =IF($A21="","",IF(E21<>"ランチ+ディナー",0,IF(AND(W21=1,T21>=設定!$B$13),(1-設定!$B$17)*F21*J21+設定!$B$17*T21*設定!$B$22,F21*J21)*K21*N(L21))) | N21: =IF($A21="","",IF(E21="休業",0,IF(W21=1,(1-設定!$B$17)*G21*J21+設定!$B$17*U21*設定!$B$22,G21*J21)*K21*N(L21))) | O21: =IF($A21="","",ROUND(M21+N21,0)) | P21: =IF($A21="","",売上予測貼付用!S16) | Q21: =IF($A21="","",IFERROR(P21/O21,"")) | T21: =IF($A21="","",IF(COUNTIF(前年当月データ!$A:$A,$A21-364)=0,"",SUMIFS(前年当月データ!$Q:$Q,前年当月データ!$A:$A,$A21-364,前年当月データ!$K:$K,">=6",前年当月データ!$K:$K,"<"&設定!$B$10))) | U21: =IF(T21="","",SUMIFS(前年当月データ!$Q:$Q,前年当月データ!$A:$A,$A21-364)-T21) | V21: =IF(T21="","",IF(COUNTIF(祝日!$A:$A,($A21-364))>0,"祝",CHOOSE(WEEKDAY(($A21-364),2),"月","火","水","木","金","土","日"))) | W21: =IF($A21="",0,IF(AND(設定!$B$17>0,N(U21)>0,C21<>"祝",V21<>"祝",E21<>"休業"),1,0)) -> 0
A22: =IF(OR(設定!$B$7="",14>設定!$B$8),"",設定!$B$7+13) | B22: =IF($A22="","",CHOOSE(WEEKDAY($A22,2),"月","火","水","木","金","土","日")) | C22: =IF($A22="","",IF(COUNTIF(祝日!$A:$A,$A22)>0,"祝",CHOOSE(WEEKDAY($A22,2),"月","火","水","木","金","土","日"))) | E22: =IF($A22="","",IF(D22<>"",D22,IF(IF(OR(C22="土",C22="日",C22="祝"),設定!$B$12,設定!$B$11)="あり","ランチ+ディナー","ディナーのみ"))) | F22: =IF($A22="","",IF(E22="ランチ+ディナー",INDEX(集計!$M$38:$M$45,MATCH(C22,集計!$A$38:$A$45,0)),0)) | G22: =IF($A22="","",IF(E22="休業",0,INDEX(集計!$L$38:$L$45,MATCH(C22,集計!$A$38:$A$45,0)))) | H22: =IF(W22=1,$A22-364,"") | I22: =IF(W22=1,IF(AND(E22="ランチ+ディナー",T22>=設定!$B$13),T22,0)+U22,"") | J22: =IF($A22="","",設定!$B$21) | K22: =IF($A22="","",設定!$B$19) | L22: 1 | M22: =IF($A22="","",IF(E22<>"ランチ+ディナー",0,IF(AND(W22=1,T22>=設定!$B$13),(1-設定!$B$17)*F22*J22+設定!$B$17*T22*設定!$B$22,F22*J22)*K22*N(L22))) | N22: =IF($A22="","",IF(E22="休業",0,IF(W22=1,(1-設定!$B$17)*G22*J22+設定!$B$17*U22*設定!$B$22,G22*J22)*K22*N(L22))) | O22: =IF($A22="","",ROUND(M22+N22,0)) | P22: =IF($A22="","",売上予測貼付用!S17) | Q22: =IF($A22="","",IFERROR(P22/O22,"")) | T22: =IF($A22="","",IF(COUNTIF(前年当月データ!$A:$A,$A22-364)=0,"",SUMIFS(前年当月データ!$Q:$Q,前年当月データ!$A:$A,$A22-364,前年当月データ!$K:$K,">=6",前年当月データ!$K:$K,"<"&設定!$B$10))) | U22: =IF(T22="","",SUMIFS(前年当月データ!$Q:$Q,前年当月データ!$A:$A,$A22-364)-T22) | V22: =IF(T22="","",IF(COUNTIF(祝日!$A:$A,($A22-364))>0,"祝",CHOOSE(WEEKDAY(($A22-364),2),"月","火","水","木","金","土","日"))) | W22: =IF($A22="",0,IF(AND(設定!$B$17>0,N(U22)>0,C22<>"祝",V22<>"祝",E22<>"休業"),1,0)) -> 0
A23: =IF(OR(設定!$B$7="",15>設定!$B$8),"",設定!$B$7+14) | B23: =IF($A23="","",CHOOSE(WEEKDAY($A23,2),"月","火","水","木","金","土","日")) | C23: =IF($A23="","",IF(COUNTIF(祝日!$A:$A,$A23)>0,"祝",CHOOSE(WEEKDAY($A23,2),"月","火","水","木","金","土","日"))) | E23: =IF($A23="","",IF(D23<>"",D23,IF(IF(OR(C23="土",C23="日",C23="祝"),設定!$B$12,設定!$B$11)="あり","ランチ+ディナー","ディナーのみ"))) | F23: =IF($A23="","",IF(E23="ランチ+ディナー",INDEX(集計!$M$38:$M$45,MATCH(C23,集計!$A$38:$A$45,0)),0)) | G23: =IF($A23="","",IF(E23="休業",0,INDEX(集計!$L$38:$L$45,MATCH(C23,集計!$A$38:$A$45,0)))) | H23: =IF(W23=1,$A23-364,"") | I23: =IF(W23=1,IF(AND(E23="ランチ+ディナー",T23>=設定!$B$13),T23,0)+U23,"") | J23: =IF($A23="","",設定!$B$21) | K23: =IF($A23="","",設定!$B$19) | L23: 1 | M23: =IF($A23="","",IF(E23<>"ランチ+ディナー",0,IF(AND(W23=1,T23>=設定!$B$13),(1-設定!$B$17)*F23*J23+設定!$B$17*T23*設定!$B$22,F23*J23)*K23*N(L23))) | N23: =IF($A23="","",IF(E23="休業",0,IF(W23=1,(1-設定!$B$17)*G23*J23+設定!$B$17*U23*設定!$B$22,G23*J23)*K23*N(L23))) | O23: =IF($A23="","",ROUND(M23+N23,0)) | P23: =IF($A23="","",売上予測貼付用!S18) | Q23: =IF($A23="","",IFERROR(P23/O23,"")) | T23: =IF($A23="","",IF(COUNTIF(前年当月データ!$A:$A,$A23-364)=0,"",SUMIFS(前年当月データ!$Q:$Q,前年当月データ!$A:$A,$A23-364,前年当月データ!$K:$K,">=6",前年当月データ!$K:$K,"<"&設定!$B$10))) | U23: =IF(T23="","",SUMIFS(前年当月データ!$Q:$Q,前年当月データ!$A:$A,$A23-364)-T23) | V23: =IF(T23="","",IF(COUNTIF(祝日!$A:$A,($A23-364))>0,"祝",CHOOSE(WEEKDAY(($A23-364),2),"月","火","水","木","金","土","日"))) | W23: =IF($A23="",0,IF(AND(設定!$B$17>0,N(U23)>0,C23<>"祝",V23<>"祝",E23<>"休業"),1,0)) -> 0
A24: =IF(OR(設定!$B$7="",16>設定!$B$8),"",設定!$B$7+15) | B24: =IF($A24="","",CHOOSE(WEEKDAY($A24,2),"月","火","水","木","金","土","日")) | C24: =IF($A24="","",IF(COUNTIF(祝日!$A:$A,$A24)>0,"祝",CHOOSE(WEEKDAY($A24,2),"月","火","水","木","金","土","日"))) | E24: =IF($A24="","",IF(D24<>"",D24,IF(IF(OR(C24="土",C24="日",C24="祝"),設定!$B$12,設定!$B$11)="あり","ランチ+ディナー","ディナーのみ"))) | F24: =IF($A24="","",IF(E24="ランチ+ディナー",INDEX(集計!$M$38:$M$45,MATCH(C24,集計!$A$38:$A$45,0)),0)) | G24: =IF($A24="","",IF(E24="休業",0,INDEX(集計!$L$38:$L$45,MATCH(C24,集計!$A$38:$A$45,0)))) | H24: =IF(W24=1,$A24-364,"") | I24: =IF(W24=1,IF(AND(E24="ランチ+ディナー",T24>=設定!$B$13),T24,0)+U24,"") | J24: =IF($A24="","",設定!$B$21) | K24: =IF($A24="","",設定!$B$19) | L24: 1 | M24: =IF($A24="","",IF(E24<>"ランチ+ディナー",0,IF(AND(W24=1,T24>=設定!$B$13),(1-設定!$B$17)*F24*J24+設定!$B$17*T24*設定!$B$22,F24*J24)*K24*N(L24))) | N24: =IF($A24="","",IF(E24="休業",0,IF(W24=1,(1-設定!$B$17)*G24*J24+設定!$B$17*U24*設定!$B$22,G24*J24)*K24*N(L24))) | O24: =IF($A24="","",ROUND(M24+N24,0)) | P24: =IF($A24="","",売上予測貼付用!S19) | Q24: =IF($A24="","",IFERROR(P24/O24,"")) | T24: =IF($A24="","",IF(COUNTIF(前年当月データ!$A:$A,$A24-364)=0,"",SUMIFS(前年当月データ!$Q:$Q,前年当月データ!$A:$A,$A24-364,前年当月データ!$K:$K,">=6",前年当月データ!$K:$K,"<"&設定!$B$10))) | U24: =IF(T24="","",SUMIFS(前年当月データ!$Q:$Q,前年当月データ!$A:$A,$A24-364)-T24) | V24: =IF(T24="","",IF(COUNTIF(祝日!$A:$A,($A24-364))>0,"祝",CHOOSE(WEEKDAY(($A24-364),2),"月","火","水","木","金","土","日"))) | W24: =IF($A24="",0,IF(AND(設定!$B$17>0,N(U24)>0,C24<>"祝",V24<>"祝",E24<>"休業"),1,0)) -> 0
A25: =IF(OR(設定!$B$7="",17>設定!$B$8),"",設定!$B$7+16) | B25: =IF($A25="","",CHOOSE(WEEKDAY($A25,2),"月","火","水","木","金","土","日")) | C25: =IF($A25="","",IF(COUNTIF(祝日!$A:$A,$A25)>0,"祝",CHOOSE(WEEKDAY($A25,2),"月","火","水","木","金","土","日"))) | E25: =IF($A25="","",IF(D25<>"",D25,IF(IF(OR(C25="土",C25="日",C25="祝"),設定!$B$12,設定!$B$11)="あり","ランチ+ディナー","ディナーのみ"))) | F25: =IF($A25="","",IF(E25="ランチ+ディナー",INDEX(集計!$M$38:$M$45,MATCH(C25,集計!$A$38:$A$45,0)),0)) | G25: =IF($A25="","",IF(E25="休業",0,INDEX(集計!$L$38:$L$45,MATCH(C25,集計!$A$38:$A$45,0)))) | H25: =IF(W25=1,$A25-364,"") | I25: =IF(W25=1,IF(AND(E25="ランチ+ディナー",T25>=設定!$B$13),T25,0)+U25,"") | J25: =IF($A25="","",設定!$B$21) | K25: =IF($A25="","",設定!$B$19) | L25: 1 | M25: =IF($A25="","",IF(E25<>"ランチ+ディナー",0,IF(AND(W25=1,T25>=設定!$B$13),(1-設定!$B$17)*F25*J25+設定!$B$17*T25*設定!$B$22,F25*J25)*K25*N(L25))) | N25: =IF($A25="","",IF(E25="休業",0,IF(W25=1,(1-設定!$B$17)*G25*J25+設定!$B$17*U25*設定!$B$22,G25*J25)*K25*N(L25))) | O25: =IF($A25="","",ROUND(M25+N25,0)) | P25: =IF($A25="","",売上予測貼付用!S20) | Q25: =IF($A25="","",IFERROR(P25/O25,"")) | T25: =IF($A25="","",IF(COUNTIF(前年当月データ!$A:$A,$A25-364)=0,"",SUMIFS(前年当月データ!$Q:$Q,前年当月データ!$A:$A,$A25-364,前年当月データ!$K:$K,">=6",前年当月データ!$K:$K,"<"&設定!$B$10))) | U25: =IF(T25="","",SUMIFS(前年当月データ!$Q:$Q,前年当月データ!$A:$A,$A25-364)-T25) | V25: =IF(T25="","",IF(COUNTIF(祝日!$A:$A,($A25-364))>0,"祝",CHOOSE(WEEKDAY(($A25-364),2),"月","火","水","木","金","土","日"))) | W25: =IF($A25="",0,IF(AND(設定!$B$17>0,N(U25)>0,C25<>"祝",V25<>"祝",E25<>"休業"),1,0)) -> 0
A26: =IF(OR(設定!$B$7="",18>設定!$B$8),"",設定!$B$7+17) | B26: =IF($A26="","",CHOOSE(WEEKDAY($A26,2),"月","火","水","木","金","土","日")) | C26: =IF($A26="","",IF(COUNTIF(祝日!$A:$A,$A26)>0,"祝",CHOOSE(WEEKDAY($A26,2),"月","火","水","木","金","土","日"))) | E26: =IF($A26="","",IF(D26<>"",D26,IF(IF(OR(C26="土",C26="日",C26="祝"),設定!$B$12,設定!$B$11)="あり","ランチ+ディナー","ディナーのみ"))) | F26: =IF($A26="","",IF(E26="ランチ+ディナー",INDEX(集計!$M$38:$M$45,MATCH(C26,集計!$A$38:$A$45,0)),0)) | G26: =IF($A26="","",IF(E26="休業",0,INDEX(集計!$L$38:$L$45,MATCH(C26,集計!$A$38:$A$45,0)))) | H26: =IF(W26=1,$A26-364,"") | I26: =IF(W26=1,IF(AND(E26="ランチ+ディナー",T26>=設定!$B$13),T26,0)+U26,"") | J26: =IF($A26="","",設定!$B$21) | K26: =IF($A26="","",設定!$B$19) | L26: 1 | M26: =IF($A26="","",IF(E26<>"ランチ+ディナー",0,IF(AND(W26=1,T26>=設定!$B$13),(1-設定!$B$17)*F26*J26+設定!$B$17*T26*設定!$B$22,F26*J26)*K26*N(L26))) | N26: =IF($A26="","",IF(E26="休業",0,IF(W26=1,(1-設定!$B$17)*G26*J26+設定!$B$17*U26*設定!$B$22,G26*J26)*K26*N(L26))) | O26: =IF($A26="","",ROUND(M26+N26,0)) | P26: =IF($A26="","",売上予測貼付用!S21) | Q26: =IF($A26="","",IFERROR(P26/O26,"")) | T26: =IF($A26="","",IF(COUNTIF(前年当月データ!$A:$A,$A26-364)=0,"",SUMIFS(前年当月データ!$Q:$Q,前年当月データ!$A:$A,$A26-364,前年当月データ!$K:$K,">=6",前年当月データ!$K:$K,"<"&設定!$B$10))) | U26: =IF(T26="","",SUMIFS(前年当月データ!$Q:$Q,前年当月データ!$A:$A,$A26-364)-T26) | V26: =IF(T26="","",IF(COUNTIF(祝日!$A:$A,($A26-364))>0,"祝",CHOOSE(WEEKDAY(($A26-364),2),"月","火","水","木","金","土","日"))) | W26: =IF($A26="",0,IF(AND(設定!$B$17>0,N(U26)>0,C26<>"祝",V26<>"祝",E26<>"休業"),1,0)) -> 0
A27: =IF(OR(設定!$B$7="",19>設定!$B$8),"",設定!$B$7+18) | B27: =IF($A27="","",CHOOSE(WEEKDAY($A27,2),"月","火","水","木","金","土","日")) | C27: =IF($A27="","",IF(COUNTIF(祝日!$A:$A,$A27)>0,"祝",CHOOSE(WEEKDAY($A27,2),"月","火","水","木","金","土","日"))) | E27: =IF($A27="","",IF(D27<>"",D27,IF(IF(OR(C27="土",C27="日",C27="祝"),設定!$B$12,設定!$B$11)="あり","ランチ+ディナー","ディナーのみ"))) | F27: =IF($A27="","",IF(E27="ランチ+ディナー",INDEX(集計!$M$38:$M$45,MATCH(C27,集計!$A$38:$A$45,0)),0)) | G27: =IF($A27="","",IF(E27="休業",0,INDEX(集計!$L$38:$L$45,MATCH(C27,集計!$A$38:$A$45,0)))) | H27: =IF(W27=1,$A27-364,"") | I27: =IF(W27=1,IF(AND(E27="ランチ+ディナー",T27>=設定!$B$13),T27,0)+U27,"") | J27: =IF($A27="","",設定!$B$21) | K27: =IF($A27="","",設定!$B$19) | L27: 1 | M27: =IF($A27="","",IF(E27<>"ランチ+ディナー",0,IF(AND(W27=1,T27>=設定!$B$13),(1-設定!$B$17)*F27*J27+設定!$B$17*T27*設定!$B$22,F27*J27)*K27*N(L27))) | N27: =IF($A27="","",IF(E27="休業",0,IF(W27=1,(1-設定!$B$17)*G27*J27+設定!$B$17*U27*設定!$B$22,G27*J27)*K27*N(L27))) | O27: =IF($A27="","",ROUND(M27+N27,0)) | P27: =IF($A27="","",売上予測貼付用!S22) | Q27: =IF($A27="","",IFERROR(P27/O27,"")) | T27: =IF($A27="","",IF(COUNTIF(前年当月データ!$A:$A,$A27-364)=0,"",SUMIFS(前年当月データ!$Q:$Q,前年当月データ!$A:$A,$A27-364,前年当月データ!$K:$K,">=6",前年当月データ!$K:$K,"<"&設定!$B$10))) | U27: =IF(T27="","",SUMIFS(前年当月データ!$Q:$Q,前年当月データ!$A:$A,$A27-364)-T27) | V27: =IF(T27="","",IF(COUNTIF(祝日!$A:$A,($A27-364))>0,"祝",CHOOSE(WEEKDAY(($A27-364),2),"月","火","水","木","金","土","日"))) | W27: =IF($A27="",0,IF(AND(設定!$B$17>0,N(U27)>0,C27<>"祝",V27<>"祝",E27<>"休業"),1,0)) -> 0
A28: =IF(OR(設定!$B$7="",20>設定!$B$8),"",設定!$B$7+19) | B28: =IF($A28="","",CHOOSE(WEEKDAY($A28,2),"月","火","水","木","金","土","日")) | C28: =IF($A28="","",IF(COUNTIF(祝日!$A:$A,$A28)>0,"祝",CHOOSE(WEEKDAY($A28,2),"月","火","水","木","金","土","日"))) | E28: =IF($A28="","",IF(D28<>"",D28,IF(IF(OR(C28="土",C28="日",C28="祝"),設定!$B$12,設定!$B$11)="あり","ランチ+ディナー","ディナーのみ"))) | F28: =IF($A28="","",IF(E28="ランチ+ディナー",INDEX(集計!$M$38:$M$45,MATCH(C28,集計!$A$38:$A$45,0)),0)) | G28: =IF($A28="","",IF(E28="休業",0,INDEX(集計!$L$38:$L$45,MATCH(C28,集計!$A$38:$A$45,0)))) | H28: =IF(W28=1,$A28-364,"") | I28: =IF(W28=1,IF(AND(E28="ランチ+ディナー",T28>=設定!$B$13),T28,0)+U28,"") | J28: =IF($A28="","",設定!$B$21) | K28: =IF($A28="","",設定!$B$19) | L28: 1 | M28: =IF($A28="","",IF(E28<>"ランチ+ディナー",0,IF(AND(W28=1,T28>=設定!$B$13),(1-設定!$B$17)*F28*J28+設定!$B$17*T28*設定!$B$22,F28*J28)*K28*N(L28))) | N28: =IF($A28="","",IF(E28="休業",0,IF(W28=1,(1-設定!$B$17)*G28*J28+設定!$B$17*U28*設定!$B$22,G28*J28)*K28*N(L28))) | O28: =IF($A28="","",ROUND(M28+N28,0)) | P28: =IF($A28="","",売上予測貼付用!S23) | Q28: =IF($A28="","",IFERROR(P28/O28,"")) | T28: =IF($A28="","",IF(COUNTIF(前年当月データ!$A:$A,$A28-364)=0,"",SUMIFS(前年当月データ!$Q:$Q,前年当月データ!$A:$A,$A28-364,前年当月データ!$K:$K,">=6",前年当月データ!$K:$K,"<"&設定!$B$10))) | U28: =IF(T28="","",SUMIFS(前年当月データ!$Q:$Q,前年当月データ!$A:$A,$A28-364)-T28) | V28: =IF(T28="","",IF(COUNTIF(祝日!$A:$A,($A28-364))>0,"祝",CHOOSE(WEEKDAY(($A28-364),2),"月","火","水","木","金","土","日"))) | W28: =IF($A28="",0,IF(AND(設定!$B$17>0,N(U28)>0,C28<>"祝",V28<>"祝",E28<>"休業"),1,0)) -> 0
A29: =IF(OR(設定!$B$7="",21>設定!$B$8),"",設定!$B$7+20) | B29: =IF($A29="","",CHOOSE(WEEKDAY($A29,2),"月","火","水","木","金","土","日")) | C29: =IF($A29="","",IF(COUNTIF(祝日!$A:$A,$A29)>0,"祝",CHOOSE(WEEKDAY($A29,2),"月","火","水","木","金","土","日"))) | E29: =IF($A29="","",IF(D29<>"",D29,IF(IF(OR(C29="土",C29="日",C29="祝"),設定!$B$12,設定!$B$11)="あり","ランチ+ディナー","ディナーのみ"))) | F29: =IF($A29="","",IF(E29="ランチ+ディナー",INDEX(集計!$M$38:$M$45,MATCH(C29,集計!$A$38:$A$45,0)),0)) | G29: =IF($A29="","",IF(E29="休業",0,INDEX(集計!$L$38:$L$45,MATCH(C29,集計!$A$38:$A$45,0)))) | H29: =IF(W29=1,$A29-364,"") | I29: =IF(W29=1,IF(AND(E29="ランチ+ディナー",T29>=設定!$B$13),T29,0)+U29,"") | J29: =IF($A29="","",設定!$B$21) | K29: =IF($A29="","",設定!$B$19) | L29: 1 | M29: =IF($A29="","",IF(E29<>"ランチ+ディナー",0,IF(AND(W29=1,T29>=設定!$B$13),(1-設定!$B$17)*F29*J29+設定!$B$17*T29*設定!$B$22,F29*J29)*K29*N(L29))) | N29: =IF($A29="","",IF(E29="休業",0,IF(W29=1,(1-設定!$B$17)*G29*J29+設定!$B$17*U29*設定!$B$22,G29*J29)*K29*N(L29))) | O29: =IF($A29="","",ROUND(M29+N29,0)) | P29: =IF($A29="","",売上予測貼付用!S24) | Q29: =IF($A29="","",IFERROR(P29/O29,"")) | T29: =IF($A29="","",IF(COUNTIF(前年当月データ!$A:$A,$A29-364)=0,"",SUMIFS(前年当月データ!$Q:$Q,前年当月データ!$A:$A,$A29-364,前年当月データ!$K:$K,">=6",前年当月データ!$K:$K,"<"&設定!$B$10))) | U29: =IF(T29="","",SUMIFS(前年当月データ!$Q:$Q,前年当月データ!$A:$A,$A29-364)-T29) | V29: =IF(T29="","",IF(COUNTIF(祝日!$A:$A,($A29-364))>0,"祝",CHOOSE(WEEKDAY(($A29-364),2),"月","火","水","木","金","土","日"))) | W29: =IF($A29="",0,IF(AND(設定!$B$17>0,N(U29)>0,C29<>"祝",V29<>"祝",E29<>"休業"),1,0)) -> 0
A30: =IF(OR(設定!$B$7="",22>設定!$B$8),"",設定!$B$7+21) | B30: =IF($A30="","",CHOOSE(WEEKDAY($A30,2),"月","火","水","木","金","土","日")) | C30: =IF($A30="","",IF(COUNTIF(祝日!$A:$A,$A30)>0,"祝",CHOOSE(WEEKDAY($A30,2),"月","火","水","木","金","土","日"))) | E30: =IF($A30="","",IF(D30<>"",D30,IF(IF(OR(C30="土",C30="日",C30="祝"),設定!$B$12,設定!$B$11)="あり","ランチ+ディナー","ディナーのみ"))) | F30: =IF($A30="","",IF(E30="ランチ+ディナー",INDEX(集計!$M$38:$M$45,MATCH(C30,集計!$A$38:$A$45,0)),0)) | G30: =IF($A30="","",IF(E30="休業",0,INDEX(集計!$L$38:$L$45,MATCH(C30,集計!$A$38:$A$45,0)))) | H30: =IF(W30=1,$A30-364,"") | I30: =IF(W30=1,IF(AND(E30="ランチ+ディナー",T30>=設定!$B$13),T30,0)+U30,"") | J30: =IF($A30="","",設定!$B$21) | K30: =IF($A30="","",設定!$B$19) | L30: 1 | M30: =IF($A30="","",IF(E30<>"ランチ+ディナー",0,IF(AND(W30=1,T30>=設定!$B$13),(1-設定!$B$17)*F30*J30+設定!$B$17*T30*設定!$B$22,F30*J30)*K30*N(L30))) | N30: =IF($A30="","",IF(E30="休業",0,IF(W30=1,(1-設定!$B$17)*G30*J30+設定!$B$17*U30*設定!$B$22,G30*J30)*K30*N(L30))) | O30: =IF($A30="","",ROUND(M30+N30,0)) | P30: =IF($A30="","",売上予測貼付用!S25) | Q30: =IF($A30="","",IFERROR(P30/O30,"")) | T30: =IF($A30="","",IF(COUNTIF(前年当月データ!$A:$A,$A30-364)=0,"",SUMIFS(前年当月データ!$Q:$Q,前年当月データ!$A:$A,$A30-364,前年当月データ!$K:$K,">=6",前年当月データ!$K:$K,"<"&設定!$B$10))) | U30: =IF(T30="","",SUMIFS(前年当月データ!$Q:$Q,前年当月データ!$A:$A,$A30-364)-T30) | V30: =IF(T30="","",IF(COUNTIF(祝日!$A:$A,($A30-364))>0,"祝",CHOOSE(WEEKDAY(($A30-364),2),"月","火","水","木","金","土","日"))) | W30: =IF($A30="",0,IF(AND(設定!$B$17>0,N(U30)>0,C30<>"祝",V30<>"祝",E30<>"休業"),1,0)) -> 0
A31: =IF(OR(設定!$B$7="",23>設定!$B$8),"",設定!$B$7+22) | B31: =IF($A31="","",CHOOSE(WEEKDAY($A31,2),"月","火","水","木","金","土","日")) | C31: =IF($A31="","",IF(COUNTIF(祝日!$A:$A,$A31)>0,"祝",CHOOSE(WEEKDAY($A31,2),"月","火","水","木","金","土","日"))) | E31: =IF($A31="","",IF(D31<>"",D31,IF(IF(OR(C31="土",C31="日",C31="祝"),設定!$B$12,設定!$B$11)="あり","ランチ+ディナー","ディナーのみ"))) | F31: =IF($A31="","",IF(E31="ランチ+ディナー",INDEX(集計!$M$38:$M$45,MATCH(C31,集計!$A$38:$A$45,0)),0)) | G31: =IF($A31="","",IF(E31="休業",0,INDEX(集計!$L$38:$L$45,MATCH(C31,集計!$A$38:$A$45,0)))) | H31: =IF(W31=1,$A31-364,"") | I31: =IF(W31=1,IF(AND(E31="ランチ+ディナー",T31>=設定!$B$13),T31,0)+U31,"") | J31: =IF($A31="","",設定!$B$21) | K31: =IF($A31="","",設定!$B$19) | L31: 1 | M31: =IF($A31="","",IF(E31<>"ランチ+ディナー",0,IF(AND(W31=1,T31>=設定!$B$13),(1-設定!$B$17)*F31*J31+設定!$B$17*T31*設定!$B$22,F31*J31)*K31*N(L31))) | N31: =IF($A31="","",IF(E31="休業",0,IF(W31=1,(1-設定!$B$17)*G31*J31+設定!$B$17*U31*設定!$B$22,G31*J31)*K31*N(L31))) | O31: =IF($A31="","",ROUND(M31+N31,0)) | P31: =IF($A31="","",売上予測貼付用!S26) | Q31: =IF($A31="","",IFERROR(P31/O31,"")) | T31: =IF($A31="","",IF(COUNTIF(前年当月データ!$A:$A,$A31-364)=0,"",SUMIFS(前年当月データ!$Q:$Q,前年当月データ!$A:$A,$A31-364,前年当月データ!$K:$K,">=6",前年当月データ!$K:$K,"<"&設定!$B$10))) | U31: =IF(T31="","",SUMIFS(前年当月データ!$Q:$Q,前年当月データ!$A:$A,$A31-364)-T31) | V31: =IF(T31="","",IF(COUNTIF(祝日!$A:$A,($A31-364))>0,"祝",CHOOSE(WEEKDAY(($A31-364),2),"月","火","水","木","金","土","日"))) | W31: =IF($A31="",0,IF(AND(設定!$B$17>0,N(U31)>0,C31<>"祝",V31<>"祝",E31<>"休業"),1,0)) -> 0
A32: =IF(OR(設定!$B$7="",24>設定!$B$8),"",設定!$B$7+23) | B32: =IF($A32="","",CHOOSE(WEEKDAY($A32,2),"月","火","水","木","金","土","日")) | C32: =IF($A32="","",IF(COUNTIF(祝日!$A:$A,$A32)>0,"祝",CHOOSE(WEEKDAY($A32,2),"月","火","水","木","金","土","日"))) | E32: =IF($A32="","",IF(D32<>"",D32,IF(IF(OR(C32="土",C32="日",C32="祝"),設定!$B$12,設定!$B$11)="あり","ランチ+ディナー","ディナーのみ"))) | F32: =IF($A32="","",IF(E32="ランチ+ディナー",INDEX(集計!$M$38:$M$45,MATCH(C32,集計!$A$38:$A$45,0)),0)) | G32: =IF($A32="","",IF(E32="休業",0,INDEX(集計!$L$38:$L$45,MATCH(C32,集計!$A$38:$A$45,0)))) | H32: =IF(W32=1,$A32-364,"") | I32: =IF(W32=1,IF(AND(E32="ランチ+ディナー",T32>=設定!$B$13),T32,0)+U32,"") | J32: =IF($A32="","",設定!$B$21) | K32: =IF($A32="","",設定!$B$19) | L32: 1 | M32: =IF($A32="","",IF(E32<>"ランチ+ディナー",0,IF(AND(W32=1,T32>=設定!$B$13),(1-設定!$B$17)*F32*J32+設定!$B$17*T32*設定!$B$22,F32*J32)*K32*N(L32))) | N32: =IF($A32="","",IF(E32="休業",0,IF(W32=1,(1-設定!$B$17)*G32*J32+設定!$B$17*U32*設定!$B$22,G32*J32)*K32*N(L32))) | O32: =IF($A32="","",ROUND(M32+N32,0)) | P32: =IF($A32="","",売上予測貼付用!S27) | Q32: =IF($A32="","",IFERROR(P32/O32,"")) | T32: =IF($A32="","",IF(COUNTIF(前年当月データ!$A:$A,$A32-364)=0,"",SUMIFS(前年当月データ!$Q:$Q,前年当月データ!$A:$A,$A32-364,前年当月データ!$K:$K,">=6",前年当月データ!$K:$K,"<"&設定!$B$10))) | U32: =IF(T32="","",SUMIFS(前年当月データ!$Q:$Q,前年当月データ!$A:$A,$A32-364)-T32) | V32: =IF(T32="","",IF(COUNTIF(祝日!$A:$A,($A32-364))>0,"祝",CHOOSE(WEEKDAY(($A32-364),2),"月","火","水","木","金","土","日"))) | W32: =IF($A32="",0,IF(AND(設定!$B$17>0,N(U32)>0,C32<>"祝",V32<>"祝",E32<>"休業"),1,0)) -> 0
A33: =IF(OR(設定!$B$7="",25>設定!$B$8),"",設定!$B$7+24) | B33: =IF($A33="","",CHOOSE(WEEKDAY($A33,2),"月","火","水","木","金","土","日")) | C33: =IF($A33="","",IF(COUNTIF(祝日!$A:$A,$A33)>0,"祝",CHOOSE(WEEKDAY($A33,2),"月","火","水","木","金","土","日"))) | E33: =IF($A33="","",IF(D33<>"",D33,IF(IF(OR(C33="土",C33="日",C33="祝"),設定!$B$12,設定!$B$11)="あり","ランチ+ディナー","ディナーのみ"))) | F33: =IF($A33="","",IF(E33="ランチ+ディナー",INDEX(集計!$M$38:$M$45,MATCH(C33,集計!$A$38:$A$45,0)),0)) | G33: =IF($A33="","",IF(E33="休業",0,INDEX(集計!$L$38:$L$45,MATCH(C33,集計!$A$38:$A$45,0)))) | H33: =IF(W33=1,$A33-364,"") | I33: =IF(W33=1,IF(AND(E33="ランチ+ディナー",T33>=設定!$B$13),T33,0)+U33,"") | J33: =IF($A33="","",設定!$B$21) | K33: =IF($A33="","",設定!$B$19) | L33: 1 | M33: =IF($A33="","",IF(E33<>"ランチ+ディナー",0,IF(AND(W33=1,T33>=設定!$B$13),(1-設定!$B$17)*F33*J33+設定!$B$17*T33*設定!$B$22,F33*J33)*K33*N(L33))) | N33: =IF($A33="","",IF(E33="休業",0,IF(W33=1,(1-設定!$B$17)*G33*J33+設定!$B$17*U33*設定!$B$22,G33*J33)*K33*N(L33))) | O33: =IF($A33="","",ROUND(M33+N33,0)) | P33: =IF($A33="","",売上予測貼付用!S28) | Q33: =IF($A33="","",IFERROR(P33/O33,"")) | T33: =IF($A33="","",IF(COUNTIF(前年当月データ!$A:$A,$A33-364)=0,"",SUMIFS(前年当月データ!$Q:$Q,前年当月データ!$A:$A,$A33-364,前年当月データ!$K:$K,">=6",前年当月データ!$K:$K,"<"&設定!$B$10))) | U33: =IF(T33="","",SUMIFS(前年当月データ!$Q:$Q,前年当月データ!$A:$A,$A33-364)-T33) | V33: =IF(T33="","",IF(COUNTIF(祝日!$A:$A,($A33-364))>0,"祝",CHOOSE(WEEKDAY(($A33-364),2),"月","火","水","木","金","土","日"))) | W33: =IF($A33="",0,IF(AND(設定!$B$17>0,N(U33)>0,C33<>"祝",V33<>"祝",E33<>"休業"),1,0)) -> 0
A34: =IF(OR(設定!$B$7="",26>設定!$B$8),"",設定!$B$7+25) | B34: =IF($A34="","",CHOOSE(WEEKDAY($A34,2),"月","火","水","木","金","土","日")) | C34: =IF($A34="","",IF(COUNTIF(祝日!$A:$A,$A34)>0,"祝",CHOOSE(WEEKDAY($A34,2),"月","火","水","木","金","土","日"))) | E34: =IF($A34="","",IF(D34<>"",D34,IF(IF(OR(C34="土",C34="日",C34="祝"),設定!$B$12,設定!$B$11)="あり","ランチ+ディナー","ディナーのみ"))) | F34: =IF($A34="","",IF(E34="ランチ+ディナー",INDEX(集計!$M$38:$M$45,MATCH(C34,集計!$A$38:$A$45,0)),0)) | G34: =IF($A34="","",IF(E34="休業",0,INDEX(集計!$L$38:$L$45,MATCH(C34,集計!$A$38:$A$45,0)))) | H34: =IF(W34=1,$A34-364,"") | I34: =IF(W34=1,IF(AND(E34="ランチ+ディナー",T34>=設定!$B$13),T34,0)+U34,"") | J34: =IF($A34="","",設定!$B$21) | K34: =IF($A34="","",設定!$B$19) | L34: 1 | M34: =IF($A34="","",IF(E34<>"ランチ+ディナー",0,IF(AND(W34=1,T34>=設定!$B$13),(1-設定!$B$17)*F34*J34+設定!$B$17*T34*設定!$B$22,F34*J34)*K34*N(L34))) | N34: =IF($A34="","",IF(E34="休業",0,IF(W34=1,(1-設定!$B$17)*G34*J34+設定!$B$17*U34*設定!$B$22,G34*J34)*K34*N(L34))) | O34: =IF($A34="","",ROUND(M34+N34,0)) | P34: =IF($A34="","",売上予測貼付用!S29) | Q34: =IF($A34="","",IFERROR(P34/O34,"")) | T34: =IF($A34="","",IF(COUNTIF(前年当月データ!$A:$A,$A34-364)=0,"",SUMIFS(前年当月データ!$Q:$Q,前年当月データ!$A:$A,$A34-364,前年当月データ!$K:$K,">=6",前年当月データ!$K:$K,"<"&設定!$B$10))) | U34: =IF(T34="","",SUMIFS(前年当月データ!$Q:$Q,前年当月データ!$A:$A,$A34-364)-T34) | V34: =IF(T34="","",IF(COUNTIF(祝日!$A:$A,($A34-364))>0,"祝",CHOOSE(WEEKDAY(($A34-364),2),"月","火","水","木","金","土","日"))) | W34: =IF($A34="",0,IF(AND(設定!$B$17>0,N(U34)>0,C34<>"祝",V34<>"祝",E34<>"休業"),1,0)) -> 0
A35: =IF(OR(設定!$B$7="",27>設定!$B$8),"",設定!$B$7+26) | B35: =IF($A35="","",CHOOSE(WEEKDAY($A35,2),"月","火","水","木","金","土","日")) | C35: =IF($A35="","",IF(COUNTIF(祝日!$A:$A,$A35)>0,"祝",CHOOSE(WEEKDAY($A35,2),"月","火","水","木","金","土","日"))) | E35: =IF($A35="","",IF(D35<>"",D35,IF(IF(OR(C35="土",C35="日",C35="祝"),設定!$B$12,設定!$B$11)="あり","ランチ+ディナー","ディナーのみ"))) | F35: =IF($A35="","",IF(E35="ランチ+ディナー",INDEX(集計!$M$38:$M$45,MATCH(C35,集計!$A$38:$A$45,0)),0)) | G35: =IF($A35="","",IF(E35="休業",0,INDEX(集計!$L$38:$L$45,MATCH(C35,集計!$A$38:$A$45,0)))) | H35: =IF(W35=1,$A35-364,"") | I35: =IF(W35=1,IF(AND(E35="ランチ+ディナー",T35>=設定!$B$13),T35,0)+U35,"") | J35: =IF($A35="","",設定!$B$21) | K35: =IF($A35="","",設定!$B$19) | L35: 1 | M35: =IF($A35="","",IF(E35<>"ランチ+ディナー",0,IF(AND(W35=1,T35>=設定!$B$13),(1-設定!$B$17)*F35*J35+設定!$B$17*T35*設定!$B$22,F35*J35)*K35*N(L35))) | N35: =IF($A35="","",IF(E35="休業",0,IF(W35=1,(1-設定!$B$17)*G35*J35+設定!$B$17*U35*設定!$B$22,G35*J35)*K35*N(L35))) | O35: =IF($A35="","",ROUND(M35+N35,0)) | P35: =IF($A35="","",売上予測貼付用!S30) | Q35: =IF($A35="","",IFERROR(P35/O35,"")) | T35: =IF($A35="","",IF(COUNTIF(前年当月データ!$A:$A,$A35-364)=0,"",SUMIFS(前年当月データ!$Q:$Q,前年当月データ!$A:$A,$A35-364,前年当月データ!$K:$K,">=6",前年当月データ!$K:$K,"<"&設定!$B$10))) | U35: =IF(T35="","",SUMIFS(前年当月データ!$Q:$Q,前年当月データ!$A:$A,$A35-364)-T35) | V35: =IF(T35="","",IF(COUNTIF(祝日!$A:$A,($A35-364))>0,"祝",CHOOSE(WEEKDAY(($A35-364),2),"月","火","水","木","金","土","日"))) | W35: =IF($A35="",0,IF(AND(設定!$B$17>0,N(U35)>0,C35<>"祝",V35<>"祝",E35<>"休業"),1,0)) -> 0
A36: =IF(OR(設定!$B$7="",28>設定!$B$8),"",設定!$B$7+27) | B36: =IF($A36="","",CHOOSE(WEEKDAY($A36,2),"月","火","水","木","金","土","日")) | C36: =IF($A36="","",IF(COUNTIF(祝日!$A:$A,$A36)>0,"祝",CHOOSE(WEEKDAY($A36,2),"月","火","水","木","金","土","日"))) | E36: =IF($A36="","",IF(D36<>"",D36,IF(IF(OR(C36="土",C36="日",C36="祝"),設定!$B$12,設定!$B$11)="あり","ランチ+ディナー","ディナーのみ"))) | F36: =IF($A36="","",IF(E36="ランチ+ディナー",INDEX(集計!$M$38:$M$45,MATCH(C36,集計!$A$38:$A$45,0)),0)) | G36: =IF($A36="","",IF(E36="休業",0,INDEX(集計!$L$38:$L$45,MATCH(C36,集計!$A$38:$A$45,0)))) | H36: =IF(W36=1,$A36-364,"") | I36: =IF(W36=1,IF(AND(E36="ランチ+ディナー",T36>=設定!$B$13),T36,0)+U36,"") | J36: =IF($A36="","",設定!$B$21) | K36: =IF($A36="","",設定!$B$19) | L36: 1 | M36: =IF($A36="","",IF(E36<>"ランチ+ディナー",0,IF(AND(W36=1,T36>=設定!$B$13),(1-設定!$B$17)*F36*J36+設定!$B$17*T36*設定!$B$22,F36*J36)*K36*N(L36))) | N36: =IF($A36="","",IF(E36="休業",0,IF(W36=1,(1-設定!$B$17)*G36*J36+設定!$B$17*U36*設定!$B$22,G36*J36)*K36*N(L36))) | O36: =IF($A36="","",ROUND(M36+N36,0)) | P36: =IF($A36="","",売上予測貼付用!S31) | Q36: =IF($A36="","",IFERROR(P36/O36,"")) | T36: =IF($A36="","",IF(COUNTIF(前年当月データ!$A:$A,$A36-364)=0,"",SUMIFS(前年当月データ!$Q:$Q,前年当月データ!$A:$A,$A36-364,前年当月データ!$K:$K,">=6",前年当月データ!$K:$K,"<"&設定!$B$10))) | U36: =IF(T36="","",SUMIFS(前年当月データ!$Q:$Q,前年当月データ!$A:$A,$A36-364)-T36) | V36: =IF(T36="","",IF(COUNTIF(祝日!$A:$A,($A36-364))>0,"祝",CHOOSE(WEEKDAY(($A36-364),2),"月","火","水","木","金","土","日"))) | W36: =IF($A36="",0,IF(AND(設定!$B$17>0,N(U36)>0,C36<>"祝",V36<>"祝",E36<>"休業"),1,0)) -> 0
A37: =IF(OR(設定!$B$7="",29>設定!$B$8),"",設定!$B$7+28) | B37: =IF($A37="","",CHOOSE(WEEKDAY($A37,2),"月","火","水","木","金","土","日")) | C37: =IF($A37="","",IF(COUNTIF(祝日!$A:$A,$A37)>0,"祝",CHOOSE(WEEKDAY($A37,2),"月","火","水","木","金","土","日"))) | E37: =IF($A37="","",IF(D37<>"",D37,IF(IF(OR(C37="土",C37="日",C37="祝"),設定!$B$12,設定!$B$11)="あり","ランチ+ディナー","ディナーのみ"))) | F37: =IF($A37="","",IF(E37="ランチ+ディナー",INDEX(集計!$M$38:$M$45,MATCH(C37,集計!$A$38:$A$45,0)),0)) | G37: =IF($A37="","",IF(E37="休業",0,INDEX(集計!$L$38:$L$45,MATCH(C37,集計!$A$38:$A$45,0)))) | H37: =IF(W37=1,$A37-364,"") | I37: =IF(W37=1,IF(AND(E37="ランチ+ディナー",T37>=設定!$B$13),T37,0)+U37,"") | J37: =IF($A37="","",設定!$B$21) | K37: =IF($A37="","",設定!$B$19) | L37: 1 | M37: =IF($A37="","",IF(E37<>"ランチ+ディナー",0,IF(AND(W37=1,T37>=設定!$B$13),(1-設定!$B$17)*F37*J37+設定!$B$17*T37*設定!$B$22,F37*J37)*K37*N(L37))) | N37: =IF($A37="","",IF(E37="休業",0,IF(W37=1,(1-設定!$B$17)*G37*J37+設定!$B$17*U37*設定!$B$22,G37*J37)*K37*N(L37))) | O37: =IF($A37="","",ROUND(M37+N37,0)) | P37: =IF($A37="","",売上予測貼付用!S32) | Q37: =IF($A37="","",IFERROR(P37/O37,"")) | T37: =IF($A37="","",IF(COUNTIF(前年当月データ!$A:$A,$A37-364)=0,"",SUMIFS(前年当月データ!$Q:$Q,前年当月データ!$A:$A,$A37-364,前年当月データ!$K:$K,">=6",前年当月データ!$K:$K,"<"&設定!$B$10))) | U37: =IF(T37="","",SUMIFS(前年当月データ!$Q:$Q,前年当月データ!$A:$A,$A37-364)-T37) | V37: =IF(T37="","",IF(COUNTIF(祝日!$A:$A,($A37-364))>0,"祝",CHOOSE(WEEKDAY(($A37-364),2),"月","火","水","木","金","土","日"))) | W37: =IF($A37="",0,IF(AND(設定!$B$17>0,N(U37)>0,C37<>"祝",V37<>"祝",E37<>"休業"),1,0)) -> 0
A38: =IF(OR(設定!$B$7="",30>設定!$B$8),"",設定!$B$7+29) | B38: =IF($A38="","",CHOOSE(WEEKDAY($A38,2),"月","火","水","木","金","土","日")) | C38: =IF($A38="","",IF(COUNTIF(祝日!$A:$A,$A38)>0,"祝",CHOOSE(WEEKDAY($A38,2),"月","火","水","木","金","土","日"))) | E38: =IF($A38="","",IF(D38<>"",D38,IF(IF(OR(C38="土",C38="日",C38="祝"),設定!$B$12,設定!$B$11)="あり","ランチ+ディナー","ディナーのみ"))) | F38: =IF($A38="","",IF(E38="ランチ+ディナー",INDEX(集計!$M$38:$M$45,MATCH(C38,集計!$A$38:$A$45,0)),0)) | G38: =IF($A38="","",IF(E38="休業",0,INDEX(集計!$L$38:$L$45,MATCH(C38,集計!$A$38:$A$45,0)))) | H38: =IF(W38=1,$A38-364,"") | I38: =IF(W38=1,IF(AND(E38="ランチ+ディナー",T38>=設定!$B$13),T38,0)+U38,"") | J38: =IF($A38="","",設定!$B$21) | K38: =IF($A38="","",設定!$B$19) | L38: 1 | M38: =IF($A38="","",IF(E38<>"ランチ+ディナー",0,IF(AND(W38=1,T38>=設定!$B$13),(1-設定!$B$17)*F38*J38+設定!$B$17*T38*設定!$B$22,F38*J38)*K38*N(L38))) | N38: =IF($A38="","",IF(E38="休業",0,IF(W38=1,(1-設定!$B$17)*G38*J38+設定!$B$17*U38*設定!$B$22,G38*J38)*K38*N(L38))) | O38: =IF($A38="","",ROUND(M38+N38,0)) | P38: =IF($A38="","",売上予測貼付用!S33) | Q38: =IF($A38="","",IFERROR(P38/O38,"")) | T38: =IF($A38="","",IF(COUNTIF(前年当月データ!$A:$A,$A38-364)=0,"",SUMIFS(前年当月データ!$Q:$Q,前年当月データ!$A:$A,$A38-364,前年当月データ!$K:$K,">=6",前年当月データ!$K:$K,"<"&設定!$B$10))) | U38: =IF(T38="","",SUMIFS(前年当月データ!$Q:$Q,前年当月データ!$A:$A,$A38-364)-T38) | V38: =IF(T38="","",IF(COUNTIF(祝日!$A:$A,($A38-364))>0,"祝",CHOOSE(WEEKDAY(($A38-364),2),"月","火","水","木","金","土","日"))) | W38: =IF($A38="",0,IF(AND(設定!$B$17>0,N(U38)>0,C38<>"祝",V38<>"祝",E38<>"休業"),1,0)) -> 0
A39: =IF(OR(設定!$B$7="",31>設定!$B$8),"",設定!$B$7+30) | B39: =IF($A39="","",CHOOSE(WEEKDAY($A39,2),"月","火","水","木","金","土","日")) | C39: =IF($A39="","",IF(COUNTIF(祝日!$A:$A,$A39)>0,"祝",CHOOSE(WEEKDAY($A39,2),"月","火","水","木","金","土","日"))) | E39: =IF($A39="","",IF(D39<>"",D39,IF(IF(OR(C39="土",C39="日",C39="祝"),設定!$B$12,設定!$B$11)="あり","ランチ+ディナー","ディナーのみ"))) | F39: =IF($A39="","",IF(E39="ランチ+ディナー",INDEX(集計!$M$38:$M$45,MATCH(C39,集計!$A$38:$A$45,0)),0)) | G39: =IF($A39="","",IF(E39="休業",0,INDEX(集計!$L$38:$L$45,MATCH(C39,集計!$A$38:$A$45,0)))) | H39: =IF(W39=1,$A39-364,"") | I39: =IF(W39=1,IF(AND(E39="ランチ+ディナー",T39>=設定!$B$13),T39,0)+U39,"") | J39: =IF($A39="","",設定!$B$21) | K39: =IF($A39="","",設定!$B$19) | L39: 1 | M39: =IF($A39="","",IF(E39<>"ランチ+ディナー",0,IF(AND(W39=1,T39>=設定!$B$13),(1-設定!$B$17)*F39*J39+設定!$B$17*T39*設定!$B$22,F39*J39)*K39*N(L39))) | N39: =IF($A39="","",IF(E39="休業",0,IF(W39=1,(1-設定!$B$17)*G39*J39+設定!$B$17*U39*設定!$B$22,G39*J39)*K39*N(L39))) | O39: =IF($A39="","",ROUND(M39+N39,0)) | P39: =IF($A39="","",売上予測貼付用!S34) | Q39: =IF($A39="","",IFERROR(P39/O39,"")) | T39: =IF($A39="","",IF(COUNTIF(前年当月データ!$A:$A,$A39-364)=0,"",SUMIFS(前年当月データ!$Q:$Q,前年当月データ!$A:$A,$A39-364,前年当月データ!$K:$K,">=6",前年当月データ!$K:$K,"<"&設定!$B$10))) | U39: =IF(T39="","",SUMIFS(前年当月データ!$Q:$Q,前年当月データ!$A:$A,$A39-364)-T39) | V39: =IF(T39="","",IF(COUNTIF(祝日!$A:$A,($A39-364))>0,"祝",CHOOSE(WEEKDAY(($A39-364),2),"月","火","水","木","金","土","日"))) | W39: =IF($A39="",0,IF(AND(設定!$B$17>0,N(U39)>0,C39<>"祝",V39<>"祝",E39<>"休業"),1,0)) -> 0
A40: 合計 | M40: =SUM(M9:M39) -> 0 | N40: =SUM(N9:N39) -> 0 | O40: =SUM(O9:O39) -> 0 | P40: =SUM(P9:P39) -> 0 | Q40: =IFERROR(P40/O40,"")

Sheet 時間帯別予測
A1: =IF(設定!$B$7="","時間帯別 予測客数",TEXT(設定!$B$7,"yyyy年m月")&" 時間帯別 予測客数（シフト作成用）") -> 時間帯別 予測客数
A2: 予測ランチ・予測ディナーを、同じ日タイプの時刻別構成比で配分。ディナーのみの日は夜営業開始前が0になります。小数は四捨五入表示のため合計が±数名ずれることがあります。
D3: 時間帯→ | E3: =IFERROR(INDEX(設定!$F$4:$F$27,MATCH(E4,設定!$E$4:$E$27,0)),"") -> ランチ | F3: =IFERROR(INDEX(設定!$F$4:$F$27,MATCH(F4,設定!$E$4:$E$27,0)),"") -> ランチ | G3: =IFERROR(INDEX(設定!$F$4:$F$27,MATCH(G4,設定!$E$4:$E$27,0)),"") -> ランチ | H3: =IFERROR(INDEX(設定!$F$4:$F$27,MATCH(H4,設定!$E$4:$E$27,0)),"") -> ランチ | I3: =IFERROR(INDEX(設定!$F$4:$F$27,MATCH(I4,設定!$E$4:$E$27,0)),"") -> アイドル | J3: =IFERROR(INDEX(設定!$F$4:$F$27,MATCH(J4,設定!$E$4:$E$27,0)),"") -> アイドル | K3: =IFERROR(INDEX(設定!$F$4:$F$27,MATCH(K4,設定!$E$4:$E$27,0)),"") -> アイドル | L3: =IFERROR(INDEX(設定!$F$4:$F$27,MATCH(L4,設定!$E$4:$E$27,0)),"") -> ディナー | ... Q3: =IFERROR(INDEX(設定!$F$4:$F$27,MATCH(Q4,設定!$E$4:$E$27,0)),"") -> ナイト
A4: 日付 | B4: タイプ | C4: 営業区分 | D4: 日予測 | E4: =集計!B52 -> 11 | F4: =集計!C52 -> 12 | G4: =集計!D52 -> 13 | H4: =集計!E52 -> 14 | I4: =集計!F52 -> 15 | J4: =集計!G52 -> 16 | K4: =集計!H52 -> 17 | L4: =集計!I52 -> 18 | ... Q4: =集計!N52 -> 23
A5: =予測!A9 | B5: =予測!C9 | C5: =予測!E9 | D5: =予測!O9 | E5: =IF($A5="","",IF(集計!B$52<設定!$B$10,予測!$M9,予測!$N9)*INDEX(集計!B$64:B$71,MATCH($B5,集計!$A$64:$A$71,0))) | F5: =IF($A5="","",IF(集計!C$52<設定!$B$10,予測!$M9,予測!$N9)*INDEX(集計!C$64:C$71,MATCH($B5,集計!$A$64:$A$71,0))) | G5: =IF($A5="","",IF(集計!D$52<設定!$B$10,予測!$M9,予測!$N9)*INDEX(集計!D$64:D$71,MATCH($B5,集計!$A$64:$A$71,0))) | H5: =IF($A5="","",IF(集計!E$52<設定!$B$10,予測!$M9,予測!$N9)*INDEX(集計!E$64:E$71,MATCH($B5,集計!$A$64:$A$71,0))) | I5: =IF($A5="","",IF(集計!F$52<設定!$B$10,予測!$M9,予測!$N9)*INDEX(集計!F$64:F$71,MATCH($B5,集計!$A$64:$A$71,0))) | J5: =IF($A5="","",IF(集計!G$52<設定!$B$10,予測!$M9,予測!$N9)*INDEX(集計!G$64:G$71,MATCH($B5,集計!$A$64:$A$71,0))) | K5: =IF($A5="","",IF(集計!H$52<設定!$B$10,予測!$M9,予測!$N9)*INDEX(集計!H$64:H$71,MATCH($B5,集計!$A$64:$A$71,0))) | L5: =IF($A5="","",IF(集計!I$52<設定!$B$10,予測!$M9,予測!$N9)*INDEX(集計!I$64:I$71,MATCH($B5,集計!$A$64:$A$71,0))) | ... Q5: =IF($A5="","",IF(集計!N$52<設定!$B$10,予測!$M9,予測!$N9)*INDEX(集計!N$64:N$71,MATCH($B5,集計!$A$64:$A$71,0)))
A6: =予測!A10 | B6: =予測!C10 | C6: =予測!E10 | D6: =予測!O10 | E6: =IF($A6="","",IF(集計!B$52<設定!$B$10,予測!$M10,予測!$N10)*INDEX(集計!B$64:B$71,MATCH($B6,集計!$A$64:$A$71,0))) | F6: =IF($A6="","",IF(集計!C$52<設定!$B$10,予測!$M10,予測!$N10)*INDEX(集計!C$64:C$71,MATCH($B6,集計!$A$64:$A$71,0))) | G6: =IF($A6="","",IF(集計!D$52<設定!$B$10,予測!$M10,予測!$N10)*INDEX(集計!D$64:D$71,MATCH($B6,集計!$A$64:$A$71,0))) | H6: =IF($A6="","",IF(集計!E$52<設定!$B$10,予測!$M10,予測!$N10)*INDEX(集計!E$64:E$71,MATCH($B6,集計!$A$64:$A$71,0))) | I6: =IF($A6="","",IF(集計!F$52<設定!$B$10,予測!$M10,予測!$N10)*INDEX(集計!F$64:F$71,MATCH($B6,集計!$A$64:$A$71,0))) | J6: =IF($A6="","",IF(集計!G$52<設定!$B$10,予測!$M10,予測!$N10)*INDEX(集計!G$64:G$71,MATCH($B6,集計!$A$64:$A$71,0))) | K6: =IF($A6="","",IF(集計!H$52<設定!$B$10,予測!$M10,予測!$N10)*INDEX(集計!H$64:H$71,MATCH($B6,集計!$A$64:$A$71,0))) | L6: =IF($A6="","",IF(集計!I$52<設定!$B$10,予測!$M10,予測!$N10)*INDEX(集計!I$64:I$71,MATCH($B6,集計!$A$64:$A$71,0))) | ... Q6: =IF($A6="","",IF(集計!N$52<設定!$B$10,予測!$M10,予測!$N10)*INDEX(集計!N$64:N$71,MATCH($B6,集計!$A$64:$A$71,0)))
A7: =予測!A11 | B7: =予測!C11 | C7: =予測!E11 | D7: =予測!O11 | E7: =IF($A7="","",IF(集計!B$52<設定!$B$10,予測!$M11,予測!$N11)*INDEX(集計!B$64:B$71,MATCH($B7,集計!$A$64:$A$71,0))) | F7: =IF($A7="","",IF(集計!C$52<設定!$B$10,予測!$M11,予測!$N11)*INDEX(集計!C$64:C$71,MATCH($B7,集計!$A$64:$A$71,0))) | G7: =IF($A7="","",IF(集計!D$52<設定!$B$10,予測!$M11,予測!$N11)*INDEX(集計!D$64:D$71,MATCH($B7,集計!$A$64:$A$71,0))) | H7: =IF($A7="","",IF(集計!E$52<設定!$B$10,予測!$M11,予測!$N11)*INDEX(集計!E$64:E$71,MATCH($B7,集計!$A$64:$A$71,0))) | I7: =IF($A7="","",IF(集計!F$52<設定!$B$10,予測!$M11,予測!$N11)*INDEX(集計!F$64:F$71,MATCH($B7,集計!$A$64:$A$71,0))) | J7: =IF($A7="","",IF(集計!G$52<設定!$B$10,予測!$M11,予測!$N11)*INDEX(集計!G$64:G$71,MATCH($B7,集計!$A$64:$A$71,0))) | K7: =IF($A7="","",IF(集計!H$52<設定!$B$10,予測!$M11,予測!$N11)*INDEX(集計!H$64:H$71,MATCH($B7,集計!$A$64:$A$71,0))) | L7: =IF($A7="","",IF(集計!I$52<設定!$B$10,予測!$M11,予測!$N11)*INDEX(集計!I$64:I$71,MATCH($B7,集計!$A$64:$A$71,0))) | ... Q7: =IF($A7="","",IF(集計!N$52<設定!$B$10,予測!$M11,予測!$N11)*INDEX(集計!N$64:N$71,MATCH($B7,集計!$A$64:$A$71,0)))
A8: =予測!A12 | B8: =予測!C12 | C8: =予測!E12 | D8: =予測!O12 | E8: =IF($A8="","",IF(集計!B$52<設定!$B$10,予測!$M12,予測!$N12)*INDEX(集計!B$64:B$71,MATCH($B8,集計!$A$64:$A$71,0))) | F8: =IF($A8="","",IF(集計!C$52<設定!$B$10,予測!$M12,予測!$N12)*INDEX(集計!C$64:C$71,MATCH($B8,集計!$A$64:$A$71,0))) | G8: =IF($A8="","",IF(集計!D$52<設定!$B$10,予測!$M12,予測!$N12)*INDEX(集計!D$64:D$71,MATCH($B8,集計!$A$64:$A$71,0))) | H8: =IF($A8="","",IF(集計!E$52<設定!$B$10,予測!$M12,予測!$N12)*INDEX(集計!E$64:E$71,MATCH($B8,集計!$A$64:$A$71,0))) | I8: =IF($A8="","",IF(集計!F$52<設定!$B$10,予測!$M12,予測!$N12)*INDEX(集計!F$64:F$71,MATCH($B8,集計!$A$64:$A$71,0))) | J8: =IF($A8="","",IF(集計!G$52<設定!$B$10,予測!$M12,予測!$N12)*INDEX(集計!G$64:G$71,MATCH($B8,集計!$A$64:$A$71,0))) | K8: =IF($A8="","",IF(集計!H$52<設定!$B$10,予測!$M12,予測!$N12)*INDEX(集計!H$64:H$71,MATCH($B8,集計!$A$64:$A$71,0))) | L8: =IF($A8="","",IF(集計!I$52<設定!$B$10,予測!$M12,予測!$N12)*INDEX(集計!I$64:I$71,MATCH($B8,集計!$A$64:$A$71,0))) | ... Q8: =IF($A8="","",IF(集計!N$52<設定!$B$10,予測!$M12,予測!$N12)*INDEX(集計!N$64:N$71,MATCH($B8,集計!$A$64:$A$71,0)))
A9: =予測!A13 | B9: =予測!C13 | C9: =予測!E13 | D9: =予測!O13 | E9: =IF($A9="","",IF(集計!B$52<設定!$B$10,予測!$M13,予測!$N13)*INDEX(集計!B$64:B$71,MATCH($B9,集計!$A$64:$A$71,0))) | F9: =IF($A9="","",IF(集計!C$52<設定!$B$10,予測!$M13,予測!$N13)*INDEX(集計!C$64:C$71,MATCH($B9,集計!$A$64:$A$71,0))) | G9: =IF($A9="","",IF(集計!D$52<設定!$B$10,予測!$M13,予測!$N13)*INDEX(集計!D$64:D$71,MATCH($B9,集計!$A$64:$A$71,0))) | H9: =IF($A9="","",IF(集計!E$52<設定!$B$10,予測!$M13,予測!$N13)*INDEX(集計!E$64:E$71,MATCH($B9,集計!$A$64:$A$71,0))) | I9: =IF($A9="","",IF(集計!F$52<設定!$B$10,予測!$M13,予測!$N13)*INDEX(集計!F$64:F$71,MATCH($B9,集計!$A$64:$A$71,0))) | J9: =IF($A9="","",IF(集計!G$52<設定!$B$10,予測!$M13,予測!$N13)*INDEX(集計!G$64:G$71,MATCH($B9,集計!$A$64:$A$71,0))) | K9: =IF($A9="","",IF(集計!H$52<設定!$B$10,予測!$M13,予測!$N13)*INDEX(集計!H$64:H$71,MATCH($B9,集計!$A$64:$A$71,0))) | L9: =IF($A9="","",IF(集計!I$52<設定!$B$10,予測!$M13,予測!$N13)*INDEX(集計!I$64:I$71,MATCH($B9,集計!$A$64:$A$71,0))) | ... Q9: =IF($A9="","",IF(集計!N$52<設定!$B$10,予測!$M13,予測!$N13)*INDEX(集計!N$64:N$71,MATCH($B9,集計!$A$64:$A$71,0)))
A10: =予測!A14 | B10: =予測!C14 | C10: =予測!E14 | D10: =予測!O14 | E10: =IF($A10="","",IF(集計!B$52<設定!$B$10,予測!$M14,予測!$N14)*INDEX(集計!B$64:B$71,MATCH($B10,集計!$A$64:$A$71,0))) | F10: =IF($A10="","",IF(集計!C$52<設定!$B$10,予測!$M14,予測!$N14)*INDEX(集計!C$64:C$71,MATCH($B10,集計!$A$64:$A$71,0))) | G10: =IF($A10="","",IF(集計!D$52<設定!$B$10,予測!$M14,予測!$N14)*INDEX(集計!D$64:D$71,MATCH($B10,集計!$A$64:$A$71,0))) | H10: =IF($A10="","",IF(集計!E$52<設定!$B$10,予測!$M14,予測!$N14)*INDEX(集計!E$64:E$71,MATCH($B10,集計!$A$64:$A$71,0))) | I10: =IF($A10="","",IF(集計!F$52<設定!$B$10,予測!$M14,予測!$N14)*INDEX(集計!F$64:F$71,MATCH($B10,集計!$A$64:$A$71,0))) | J10: =IF($A10="","",IF(集計!G$52<設定!$B$10,予測!$M14,予測!$N14)*INDEX(集計!G$64:G$71,MATCH($B10,集計!$A$64:$A$71,0))) | K10: =IF($A10="","",IF(集計!H$52<設定!$B$10,予測!$M14,予測!$N14)*INDEX(集計!H$64:H$71,MATCH($B10,集計!$A$64:$A$71,0))) | L10: =IF($A10="","",IF(集計!I$52<設定!$B$10,予測!$M14,予測!$N14)*INDEX(集計!I$64:I$71,MATCH($B10,集計!$A$64:$A$71,0))) | ... Q10: =IF($A10="","",IF(集計!N$52<設定!$B$10,予測!$M14,予測!$N14)*INDEX(集計!N$64:N$71,MATCH($B10,集計!$A$64:$A$71,0)))
A11: =予測!A15 | B11: =予測!C15 | C11: =予測!E15 | D11: =予測!O15 | E11: =IF($A11="","",IF(集計!B$52<設定!$B$10,予測!$M15,予測!$N15)*INDEX(集計!B$64:B$71,MATCH($B11,集計!$A$64:$A$71,0))) | F11: =IF($A11="","",IF(集計!C$52<設定!$B$10,予測!$M15,予測!$N15)*INDEX(集計!C$64:C$71,MATCH($B11,集計!$A$64:$A$71,0))) | G11: =IF($A11="","",IF(集計!D$52<設定!$B$10,予測!$M15,予測!$N15)*INDEX(集計!D$64:D$71,MATCH($B11,集計!$A$64:$A$71,0))) | H11: =IF($A11="","",IF(集計!E$52<設定!$B$10,予測!$M15,予測!$N15)*INDEX(集計!E$64:E$71,MATCH($B11,集計!$A$64:$A$71,0))) | I11: =IF($A11="","",IF(集計!F$52<設定!$B$10,予測!$M15,予測!$N15)*INDEX(集計!F$64:F$71,MATCH($B11,集計!$A$64:$A$71,0))) | J11: =IF($A11="","",IF(集計!G$52<設定!$B$10,予測!$M15,予測!$N15)*INDEX(集計!G$64:G$71,MATCH($B11,集計!$A$64:$A$71,0))) | K11: =IF($A11="","",IF(集計!H$52<設定!$B$10,予測!$M15,予測!$N15)*INDEX(集計!H$64:H$71,MATCH($B11,集計!$A$64:$A$71,0))) | L11: =IF($A11="","",IF(集計!I$52<設定!$B$10,予測!$M15,予測!$N15)*INDEX(集計!I$64:I$71,MATCH($B11,集計!$A$64:$A$71,0))) | ... Q11: =IF($A11="","",IF(集計!N$52<設定!$B$10,予測!$M15,予測!$N15)*INDEX(集計!N$64:N$71,MATCH($B11,集計!$A$64:$A$71,0)))
A12: =予測!A16 | B12: =予測!C16 | C12: =予測!E16 | D12: =予測!O16 | E12: =IF($A12="","",IF(集計!B$52<設定!$B$10,予測!$M16,予測!$N16)*INDEX(集計!B$64:B$71,MATCH($B12,集計!$A$64:$A$71,0))) | F12: =IF($A12="","",IF(集計!C$52<設定!$B$10,予測!$M16,予測!$N16)*INDEX(集計!C$64:C$71,MATCH($B12,集計!$A$64:$A$71,0))) | G12: =IF($A12="","",IF(集計!D$52<設定!$B$10,予測!$M16,予測!$N16)*INDEX(集計!D$64:D$71,MATCH($B12,集計!$A$64:$A$71,0))) | H12: =IF($A12="","",IF(集計!E$52<設定!$B$10,予測!$M16,予測!$N16)*INDEX(集計!E$64:E$71,MATCH($B12,集計!$A$64:$A$71,0))) | I12: =IF($A12="","",IF(集計!F$52<設定!$B$10,予測!$M16,予測!$N16)*INDEX(集計!F$64:F$71,MATCH($B12,集計!$A$64:$A$71,0))) | J12: =IF($A12="","",IF(集計!G$52<設定!$B$10,予測!$M16,予測!$N16)*INDEX(集計!G$64:G$71,MATCH($B12,集計!$A$64:$A$71,0))) | K12: =IF($A12="","",IF(集計!H$52<設定!$B$10,予測!$M16,予測!$N16)*INDEX(集計!H$64:H$71,MATCH($B12,集計!$A$64:$A$71,0))) | L12: =IF($A12="","",IF(集計!I$52<設定!$B$10,予測!$M16,予測!$N16)*INDEX(集計!I$64:I$71,MATCH($B12,集計!$A$64:$A$71,0))) | ... Q12: =IF($A12="","",IF(集計!N$52<設定!$B$10,予測!$M16,予測!$N16)*INDEX(集計!N$64:N$71,MATCH($B12,集計!$A$64:$A$71,0)))
A13: =予測!A17 | B13: =予測!C17 | C13: =予測!E17 | D13: =予測!O17 | E13: =IF($A13="","",IF(集計!B$52<設定!$B$10,予測!$M17,予測!$N17)*INDEX(集計!B$64:B$71,MATCH($B13,集計!$A$64:$A$71,0))) | F13: =IF($A13="","",IF(集計!C$52<設定!$B$10,予測!$M17,予測!$N17)*INDEX(集計!C$64:C$71,MATCH($B13,集計!$A$64:$A$71,0))) | G13: =IF($A13="","",IF(集計!D$52<設定!$B$10,予測!$M17,予測!$N17)*INDEX(集計!D$64:D$71,MATCH($B13,集計!$A$64:$A$71,0))) | H13: =IF($A13="","",IF(集計!E$52<設定!$B$10,予測!$M17,予測!$N17)*INDEX(集計!E$64:E$71,MATCH($B13,集計!$A$64:$A$71,0))) | I13: =IF($A13="","",IF(集計!F$52<設定!$B$10,予測!$M17,予測!$N17)*INDEX(集計!F$64:F$71,MATCH($B13,集計!$A$64:$A$71,0))) | J13: =IF($A13="","",IF(集計!G$52<設定!$B$10,予測!$M17,予測!$N17)*INDEX(集計!G$64:G$71,MATCH($B13,集計!$A$64:$A$71,0))) | K13: =IF($A13="","",IF(集計!H$52<設定!$B$10,予測!$M17,予測!$N17)*INDEX(集計!H$64:H$71,MATCH($B13,集計!$A$64:$A$71,0))) | L13: =IF($A13="","",IF(集計!I$52<設定!$B$10,予測!$M17,予測!$N17)*INDEX(集計!I$64:I$71,MATCH($B13,集計!$A$64:$A$71,0))) | ... Q13: =IF($A13="","",IF(集計!N$52<設定!$B$10,予測!$M17,予測!$N17)*INDEX(集計!N$64:N$71,MATCH($B13,集計!$A$64:$A$71,0)))
A14: =予測!A18 | B14: =予測!C18 | C14: =予測!E18 | D14: =予測!O18 | E14: =IF($A14="","",IF(集計!B$52<設定!$B$10,予測!$M18,予測!$N18)*INDEX(集計!B$64:B$71,MATCH($B14,集計!$A$64:$A$71,0))) | F14: =IF($A14="","",IF(集計!C$52<設定!$B$10,予測!$M18,予測!$N18)*INDEX(集計!C$64:C$71,MATCH($B14,集計!$A$64:$A$71,0))) | G14: =IF($A14="","",IF(集計!D$52<設定!$B$10,予測!$M18,予測!$N18)*INDEX(集計!D$64:D$71,MATCH($B14,集計!$A$64:$A$71,0))) | H14: =IF($A14="","",IF(集計!E$52<設定!$B$10,予測!$M18,予測!$N18)*INDEX(集計!E$64:E$71,MATCH($B14,集計!$A$64:$A$71,0))) | I14: =IF($A14="","",IF(集計!F$52<設定!$B$10,予測!$M18,予測!$N18)*INDEX(集計!F$64:F$71,MATCH($B14,集計!$A$64:$A$71,0))) | J14: =IF($A14="","",IF(集計!G$52<設定!$B$10,予測!$M18,予測!$N18)*INDEX(集計!G$64:G$71,MATCH($B14,集計!$A$64:$A$71,0))) | K14: =IF($A14="","",IF(集計!H$52<設定!$B$10,予測!$M18,予測!$N18)*INDEX(集計!H$64:H$71,MATCH($B14,集計!$A$64:$A$71,0))) | L14: =IF($A14="","",IF(集計!I$52<設定!$B$10,予測!$M18,予測!$N18)*INDEX(集計!I$64:I$71,MATCH($B14,集計!$A$64:$A$71,0))) | ... Q14: =IF($A14="","",IF(集計!N$52<設定!$B$10,予測!$M18,予測!$N18)*INDEX(集計!N$64:N$71,MATCH($B14,集計!$A$64:$A$71,0)))
